[Thu Oct 17 13:59:29 2019] [Out]: Args: ['C:/Users/quint/Documents/GitHub/QplayBubbles-Releaes/__main__.py', 'v1.5.1-pre5', 'v1_5_1_pre5', '16']
[Thu Oct 17 13:59:29 2019] [Out]: Launcher Path: C:\Users\quint\Documents
[Thu Oct 17 13:59:29 2019] [Out]: {'bubble': {'chance': 10, 'max-radius': 30, 'min-radius': 21, 'max-speed': 4.8, 'base-speed': 4.8, 'screen-gap': 100}, 'game': {'level-score': 10000, 'time-limit': 90, 'pause': False, 'resolution': '1920x1080', 'ship-radius': 15, 'ship-speed': 10, 'fullscreen': True, 'language': 'en'}, 'font': {'family': 'helvetica', 'size': -9}}
[Thu Oct 17 13:59:33 2019] [Err]: Exception in thread Thread-112:
[Thu Oct 17 13:59:33 2019] [Err]: Exception in thread Thread-63:
[Thu Oct 17 13:59:33 2019] [Err]: Exception in thread Thread-57:
[Thu Oct 17 13:59:33 2019] [Err]: Exception in thread Thread-83:
[Thu Oct 17 13:59:33 2019] [Err]: Exception in thread Thread-80:
[Thu Oct 17 13:59:33 2019] [Err]: Exception in thread Thread-42:
[Thu Oct 17 13:59:33 2019] [Err]: Exception in thread Thread-110:
[Thu Oct 17 13:59:33 2019] [Err]: Exception in thread Thread-125:
[Thu Oct 17 13:59:33 2019] [Err]: Exception in thread Thread-118:
[Thu Oct 17 13:59:33 2019] [Err]: Exception in thread Thread-124:
[Thu Oct 17 13:59:33 2019] [Err]: Exception in thread Thread-116:
[Thu Oct 17 13:59:33 2019] [Err]: Exception in thread Thread-86:
[Thu Oct 17 13:59:33 2019] [Err]: Exception in thread Thread-95:
[Thu Oct 17 13:59:33 2019] [Err]: Exception in thread Thread-89:
[Thu Oct 17 13:59:33 2019] [Err]: Exception in thread Thread-77:
[Thu Oct 17 13:59:33 2019] [Err]: Exception in thread Thread-90:
[Thu Oct 17 13:59:33 2019] [Err]: Exception in thread Thread-121:
[Thu Oct 17 13:59:33 2019] [Err]: Exception in thread Thread-117:
[Thu Oct 17 13:59:33 2019] [Err]: Exception in thread Thread-101:
[Thu Oct 17 13:59:33 2019] [Err]: Exception in thread Thread-114:
[Thu Oct 17 13:59:33 2019] [Err]: Exception in thread Thread-107:
[Thu Oct 17 13:59:33 2019] [Err]: Exception in thread Thread-36:
[Thu Oct 17 13:59:33 2019] [Err]: Exception in thread Thread-48:
[Thu Oct 17 13:59:33 2019] [Err]: Exception in thread Thread-115:
[Thu Oct 17 13:59:33 2019] [Err]: Exception in thread Thread-39:
[Thu Oct 17 13:59:33 2019] [Err]: Exception in thread Thread-45:
[Thu Oct 17 13:59:33 2019] [Err]: Exception in thread Thread-78:
[Thu Oct 17 13:59:33 2019] [Err]: Exception in thread Thread-111:
[Thu Oct 17 13:59:33 2019] [Err]: Exception in thread Thread-93:
[Thu Oct 17 13:59:33 2019] [Err]: Traceback (most recent call last):
[Thu Oct 17 13:59:33 2019] [Err]: Exception in thread Thread-81:
[Thu Oct 17 13:59:33 2019] [Err]: Exception in thread Thread-99:
[Thu Oct 17 13:59:33 2019] [Err]: Exception in thread Thread-98:
[Thu Oct 17 13:59:33 2019] [Err]: Traceback (most recent call last):
[Thu Oct 17 13:59:33 2019] [Err]: Traceback (most recent call last):
[Thu Oct 17 13:59:33 2019] [Err]: Exception in thread Thread-113:
[Thu Oct 17 13:59:33 2019] [Err]: Traceback (most recent call last):
[Thu Oct 17 13:59:33 2019] [Err]: Traceback (most recent call last):
[Thu Oct 17 13:59:33 2019] [Err]: Exception in thread Thread-66:
[Thu Oct 17 13:59:33 2019] [Err]: Traceback (most recent call last):
[Thu Oct 17 13:59:33 2019] [Err]: Traceback (most recent call last):
[Thu Oct 17 13:59:33 2019] [Err]:   File "C:\Users\quint\Anaconda3\lib\threading.py", line 917, in _bootstrap_inner
[Thu Oct 17 13:59:33 2019] [Err]: Traceback (most recent call last):
[Thu Oct 17 13:59:33 2019] [Err]: Traceback (most recent call last):
[Thu Oct 17 13:59:33 2019] [Err]: Exception in thread Thread-74:
[Thu Oct 17 13:59:33 2019] [Err]: Exception in thread Thread-119:
[Thu Oct 17 13:59:33 2019] [Err]: Exception in thread Thread-75:
[Thu Oct 17 13:59:33 2019] [Err]: Exception in thread Thread-104:
[Thu Oct 17 13:59:33 2019] [Err]: Exception in thread Thread-96:
[Thu Oct 17 13:59:33 2019] [Err]: Exception in thread Thread-126:
[Thu Oct 17 13:59:33 2019] [Err]: Exception in thread Thread-60:
[Thu Oct 17 13:59:33 2019] [Err]: Traceback (most recent call last):
[Thu Oct 17 13:59:33 2019] [Err]: Traceback (most recent call last):
[Thu Oct 17 13:59:33 2019] [Err]: Traceback (most recent call last):
[Thu Oct 17 13:59:33 2019] [Err]: Exception in thread Thread-87:
[Thu Oct 17 13:59:33 2019] [Err]: Traceback (most recent call last):
[Thu Oct 17 13:59:33 2019] [Err]: Exception in thread Thread-84:
[Thu Oct 17 13:59:33 2019] [Err]: Exception in thread Thread-120:
[Thu Oct 17 13:59:33 2019] [Err]: Exception in thread Thread-51:
[Thu Oct 17 13:59:33 2019] [Err]: Traceback (most recent call last):
[Thu Oct 17 13:59:33 2019] [Err]: Exception in thread Thread-92:
[Thu Oct 17 13:59:33 2019] [Err]: Traceback (most recent call last):
[Thu Oct 17 13:59:33 2019] [Err]: Exception in thread Thread-72:
[Thu Oct 17 13:59:33 2019] [Err]: Traceback (most recent call last):
[Thu Oct 17 13:59:33 2019] [Err]: Traceback (most recent call last):
[Thu Oct 17 13:59:33 2019] [Err]: Traceback (most recent call last):
[Thu Oct 17 13:59:33 2019] [Err]: Traceback (most recent call last):
[Thu Oct 17 13:59:33 2019] [Err]: Traceback (most recent call last):
[Thu Oct 17 13:59:33 2019] [Err]: Traceback (most recent call last):
[Thu Oct 17 13:59:33 2019] [Err]: Traceback (most recent call last):
[Thu Oct 17 13:59:33 2019] [Err]: Exception in thread Thread-122:
[Thu Oct 17 13:59:33 2019] [Err]: Exception in thread Thread-102:
[Thu Oct 17 13:59:33 2019] [Err]: Traceback (most recent call last):
[Thu Oct 17 13:59:33 2019] [Err]: Traceback (most recent call last):
[Thu Oct 17 13:59:33 2019] [Err]: Exception in thread Thread-108:
[Thu Oct 17 13:59:33 2019] [Err]: Traceback (most recent call last):
[Thu Oct 17 13:59:33 2019] [Err]: Traceback (most recent call last):
\threading.py", line 917, in _bootstrap_inner
, line 15, in get_coords
[Thu Oct 17 13:59:33 2019] [Err]: Exception in thread Thread-54:
[Thu Oct 17 13:59:33 2019] [Err]: Traceback (most recent call last):
[Thu Oct 17 13:59:33 2019] [Err]: Traceback (most recent call last):
[Thu Oct 17 13:59:33 2019] [Err]:   File "C:\Users\quint\Anaconda3\lib\threading.py", line 917, in _bootstrap_inner
[Thu Oct 17 13:59:33 2019] [Err]: Traceback (most recent call last):
[Thu Oct 17 13:59:33 2019] [Err]:   File "C:\Users\quint\Documents\GitHub\QplayBubbles-Releaes\lib\utils\__init__.py", line 15, in get_coords
[Thu Oct 17 13:59:33 2019] [Err]: Exception in thread Thread-69:
[Thu Oct 17 13:59:33 2019] [Err]:   File "C:\Users\quint\Documents\GitHub\QplayBubbles-Releaes\lib\utils\__init__.py", line 15, in get_coords
[Thu Oct 17 13:59:33 2019] [Err]:   File "C:\Users\quint\Anaconda3\lib\threading.py", line 917, in _bootstrap_inner
[Thu Oct 17 13:59:33 2019] [Err]:   File "C:\Users\quint\Anaconda3\lib\threading.py", line 917, in _bootstrap_inner
[Thu Oct 17 13:59:33 2019] [Err]:   File "C:\Users\quint\Documents\GitHub\QplayBubbles-Releaes\lib\utils\__init__.py", line 15, in get_coords
[Thu Oct 17 13:59:33 2019] [Err]:   File "C:\Users\quint\Documents\GitHub\QplayBubbles-Releaes\lib\utils\__init__.py", line 15, in get_coords
[Thu Oct 17 13:59:33 2019] [Err]:   File "C:\Users\quint\Documents\GitHub\QplayBubbles-Releaes\lib\utils\__init__.py", line 15, in get_coords
[Thu Oct 17 13:59:33 2019] [Err]: Traceback (most recent call last):
[Thu Oct 17 13:59:33 2019] [Err]: Traceback (most recent call last):
[Thu Oct 17 13:59:33 2019] [Err]:   File "C:\Users\quint\Anaconda3\lib\threading.py", line 917, in _bootstrap_inner
[Thu Oct 17 13:59:33 2019] [Err]:   File "C:\Users\quint\Anaconda3\lib\threading.py", line 917, in _bootstrap_inner
[Thu Oct 17 13:59:33 2019] [Err]: Traceback (most recent call last):
[Thu Oct 17 13:59:33 2019] [Err]: Traceback (most recent call last):
[Thu Oct 17 13:59:33 2019] [Err]:   File "C:\Users\quint\Documents\GitHub\QplayBubbles-Releaes\lib\utils\__init__.py", line 15, in get_coords
[Thu Oct 17 13:59:33 2019] [Err]:   File "C:\Users\quint\Documents\GitHub\QplayBubbles-Releaes\lib\utils\__init__.py", line 15, in get_coords
[Thu Oct 17 13:59:33 2019] [Err]:   File "C:\Users\quint\Documents\GitHub\QplayBubbles-Releaes\lib\utils\__init__.py", line 15, in get_coords
[Thu Oct 17 13:59:33 2019] [Err]:     pos = c.coords(id_num)
[Thu Oct 17 13:59:33 2019] [Err]:   File "C:\Users\quint\Anaconda3\lib\threading.py", line 917, in _bootstrap_inner
[Thu Oct 17 13:59:33 2019] [Err]: Traceback (most recent call last):
[Thu Oct 17 13:59:33 2019] [Err]: Traceback (most recent call last):
[Thu Oct 17 13:59:33 2019] [Err]:     self.run()
[Thu Oct 17 13:59:33 2019] [Err]:     self.run()
\quint\Documents\GitHub\QplayBubbles-Releaes\lib\utils\__init__.py", line 15, in get_coords
[Thu Oct 17 13:59:33 2019] [Err]:     self.run()
\quint\Documents\GitHub\QplayBubbles-Releaes\lib\utils\__init__.py", line 15, in get_coords
[Thu Oct 17 13:59:33 2019] [Err]:     self.run()
[Thu Oct 17 13:59:33 2019] [Err]:     self.run()
[Thu Oct 17 13:59:33 2019] [Err]:   File "C:\Users\quint\Documents\GitHub\QplayBubbles-Releaes\lib\utils\__init__.py", line 15, in get_coords
[Thu Oct 17 13:59:33 2019] [Err]:   File "C:\Users\quint\Anaconda3\lib\threading.py", line 917, in _bootstrap_inner
[Thu Oct 17 13:59:33 2019] [Err]:     self.run()
[Thu Oct 17 13:59:33 2019] [Err]:   File "C:\Users\quint\Documents\GitHub\QplayBubbles-Releaes\lib\utils\__init__.py", line 15, in get_coords
[Thu Oct 17 13:59:33 2019] [Err]:     self.run()
[Thu Oct 17 13:59:33 2019] [Err]:   File "C:\Users\quint\Documents\GitHub\QplayBubbles-Releaes\lib\utils\__init__.py", line 15, in get_coords
[Thu Oct 17 13:59:33 2019] [Err]:   File "C:\Users\quint\Documents\GitHub\QplayBubbles-Releaes\lib\utils\__init__.py", line 15, in get_coords
[Thu Oct 17 13:59:33 2019] [Err]:     pos = c.coords(id_num)
[Thu Oct 17 13:59:33 2019] [Err]:     pos = c.coords(id_num)
[Thu Oct 17 13:59:33 2019] [Err]:     pos = c.coords(id_num)
[Thu Oct 17 13:59:33 2019] [Err]:   File "C:\Users\quint\Documents\GitHub\QplayBubbles-Releaes\lib\utils\__init__.py", line 15, in get_coords
[Thu Oct 17 13:59:33 2019] [Err]:     pos = c.coords(id_num)
[Thu Oct 17 13:59:33 2019] [Err]:   File "C:\Users\quint\Anaconda3\lib\threading.py", line 865, in run
[Thu Oct 17 13:59:33 2019] [Err]:     pos = c.coords(id_num)
[Thu Oct 17 13:59:33 2019] [Err]:   File "C:\Users\quint\Anaconda3\lib\threading.py", line 917, in _bootstrap_inner
[Thu Oct 17 13:59:33 2019] [Err]:     pos = c.coords(id_num)
[Thu Oct 17 13:59:33 2019] [Err]:   File "C:\Users\quint\Documents\GitHub\QplayBubbles-Releaes\lib\utils\__init__.py", line 15, in get_coords
[Thu Oct 17 13:59:33 2019] [Err]:   File "C:\Users\quint\Anaconda3\lib\threading.py", line 917, in _bootstrap_inner
[Thu Oct 17 13:59:33 2019] [Err]:     pos = c.coords(id_num)
[Thu Oct 17 13:59:33 2019] [Err]:     self._target(*self._args, **self._kwargs)
py", line 865, in run
\__init__.py", line 15, in get_coords
[Thu Oct 17 13:59:33 2019] [Err]:   File "C:\Users\quint\Anaconda3\lib\threading.py", line 865, in run
[Thu Oct 17 13:59:33 2019] [Err]:   File "C:\Users\quint\Documents\GitHub\QplayBubbles-Releaes\lib\utils\__init__.py", line 15, in get_coords
[Thu Oct 17 13:59:33 2019] [Err]:   File "C:\Users\quint\Anaconda3\lib\threading.py", line 865, in run
[Thu Oct 17 13:59:33 2019] [Err]:   File "C:\Users\quint\Documents\GitHub\QplayBubbles-Releaes\lib\utils\__init__.py", line 15, in get_coords
[Thu Oct 17 13:59:33 2019] [Err]:   File "C:\Users\quint\Anaconda3\lib\threading.py", line 865, in run
[Thu Oct 17 13:59:33 2019] [Err]:     pos = c.coords(id_num)
[Thu Oct 17 13:59:33 2019] [Err]:     self.run()
[Thu Oct 17 13:59:33 2019] [Err]:     pos = c.coords(id_num)
[Thu Oct 17 13:59:33 2019] [Err]:     pos = c.coords(id_num)
[Thu Oct 17 13:59:33 2019] [Err]:     pos = c.coords(id_num)
[Thu Oct 17 13:59:33 2019] [Err]:     pos = c.coords(id_num)
[Thu Oct 17 13:59:33 2019] [Err]:   File "C:\Users\quint\Anaconda3\lib\threading.py", line 865, in run
[Thu Oct 17 13:59:33 2019] [Err]:   File "C:\Users\quint\Anaconda3\lib\tkinter\__init__.py", line 2469, in coords
[Thu Oct 17 13:59:33 2019] [Err]:   File "C:\Users\quint\Anaconda3\lib\threading.py", line 865, in run
[Thu Oct 17 13:59:33 2019] [Err]:     pos = c.coords(id_num)
[Thu Oct 17 13:59:33 2019] [Err]:     pos = c.coords(id_num)
[Thu Oct 17 13:59:33 2019] [Err]:   File "C:\Users\quint\Documents\GitHub\QplayBubbles-Releaes\lib\title.py", line [Thu Oct 17 13:59:33 2019] [Err]:     self.run()
ds(id_num)
nda3\lib\tkinter\__init__.py", line 2469, in coords
[Thu Oct 17 13:59:33 2019] [Err]:     self.run()
[Thu Oct 17 13:59:33 2019] [Err]:   File "C:\Users\quint\Anaconda3\lib\tkinter\__init__.py", line 2469, in coords
[Thu Oct 17 13:59:33 2019] [Err]:     pos = c.coords(id_num)
[Thu Oct 17 13:59:33 2019] [Err]:   File "C:\Users\quint\Anaconda3\lib\tkinter\__init__.py", line 2469, in coords
[Thu Oct 17 13:59:33 2019] [Err]:     self.run()
[Thu Oct 17 13:59:33 2019] [Err]:   File "C:\Users\quint\Anaconda3\lib\tkinter\__init__.py", line 2469, in coords
[Thu Oct 17 13:59:33 2019] [Err]:   File "C:\Users\quint\Anaconda3\lib\threading.py", line 865, in run
[Thu Oct 17 13:59:33 2019] [Err]:   File "C:\Users\quint\Anaconda3\lib\tkinter\__init__.py", line 2469, in coords
[Thu Oct 17 13:59:33 2019] [Err]:     pos = c.coords(id_num)
nda3\lib\tkinter\__init__.py", line 2469, in coords
[Thu Oct 17 13:59:33 2019] [Err]:   File "C:\Users\quint\Anaconda3\lib\tkinter\__init__.py", line 2469, in coords
[Thu Oct 17 13:59:33 2019] [Err]:   File "C:\Users\quint\Anaconda3\lib\tkinter\__init__.py", line 2469, in coords
[Thu Oct 17 13:59:33 2019] [Err]:   File "C:\Users\quint\Anaconda3\lib\threading.py", line 865, in run
[Thu Oct 17 13:59:33 2019] [Err]:   File "C:\Users\quint\Anaconda3\lib\tkinter\__init__.py", line 2469, in coords
[Thu Oct 17 13:59:33 2019] [Err]:   File "C:\Users\quint\Anaconda3\lib\threading.py", line 865, in run
[Thu Oct 17 13:59:33 2019] [Err]:   File "C:\Users\quint\Anaconda3\lib\tkinter\__init__.py", line 2469, in coords
[Thu Oct 17 13:59:33 2019] [Err]:     pos = c.coords(id_num)
[Thu Oct 17 13:59:33 2019] [Err]:   File "C:\Users\quint\Anaconda3\lib\threading.py", line 865, in run
[Thu Oct 17 13:59:33 2019] [Err]:     pos = c.coords(id_num)
[Thu Oct 17 13:59:33 2019] [Err]:     self._target(*self._args, **self._kwargs)
[Thu Oct 17 13:59:33 2019] [Err]:     self._target(*self._args, **self._kwargs)
[Thu Oct 17 13:59:33 2019] [Err]:   File "C:\Users\quint\Anaconda3\lib\tkinter\__init__.py", line 2469, in coords
[Thu Oct 17 13:59:33 2019] [Err]:     self.tk.call((self._w, 'coords') + args))]
[Thu Oct 17 13:59:33 2019] [Err]:     self._target(*self._args, **self._kwargs)
[Thu Oct 17 13:59:33 2019] [Err]:     self.tk.call((self._w, 'coords') + args))]
[Thu Oct 17 13:59:33 2019] [Err]:     self._target(*self._args, **self._kwargs)
[Thu Oct 17 13:59:33 2019] [Err]:     self._target(*self._args, **self._kwargs)
[Thu Oct 17 13:59:33 2019] [Err]:     self._target(*self._args, **self._kwargs)
[Thu Oct 17 13:59:33 2019] [Err]:     self._target(*self._args, **self._kwargs)
[Thu Oct 17 13:59:33 2019] [Err]:   File "C:\Users\quint\Anaconda3\lib\threading.py", line 865, in run
[Thu Oct 17 13:59:33 2019] [Err]:   File "C:\Users\quint\Anaconda3\lib\threading.py", line 865, in run
[Thu Oct 17 13:59:33 2019] [Err]:     self._target(*self._args, **self._kwargs)
[Thu Oct 17 13:59:33 2019] [Err]:   File "C:\Users\quint\Anaconda3\lib\tkinter\__init__.py", line 2469, in coords
[Thu Oct 17 13:59:33 2019] [Err]:     self.tk.call((self._w, 'coords') + args))][Thu Oct 17 13:59:33 2019] [Err]:     self.tk.call((self._w, 'coords') + args))]
[Thu Oct 17 13:59:33 2019] [Err]:     self._target(*self._args, **self._kwargs)
[Thu Oct 17 13:59:33 2019] [Err]:   File "C:\Users\quint\Anaconda3\lib\site-packages\threadsafe_tkinter\__init__.py", line 71, in <lambda>
[Thu Oct 17 13:59:33 2019] [Err]:   File "C:\Users\quint\Documents\GitHub\QplayBubbles-Releaes\lib\title.py", line 54, in <lambda>
[Thu Oct 17 13:59:33 2019] [Err]:     self.tk.call((self._w, 'coords') + args))]
[Thu Oct 17 13:59:33 2019] [Err]:   File "C:\Users\quint\Anaconda3\lib\tkinter\__init__.py", line 2469, in coords
[Thu Oct 17 13:59:33 2019] [Err]:   File "C:\Users\quint\Anaconda3\lib\tkinter\__init__.py", line 2469, in coords
[Thu Oct 17 13:59:33 2019] [Err]:     self.tk.call((self._w, 'coords') + args))]
[Thu Oct 17 13:59:33 2019] [Err]:     self._target(*self._args, **self._kwargs)
[Thu Oct 17 13:59:33 2019] [Err]:   File "C:\Users\quint\Anaconda3\lib\site-packages\threadsafe_tkinter\__init__.py", line 71, in <lambda>
[Thu Oct 17 13:59:33 2019] [Err]:     self.tk.call((self._w, 'coords') + args))]
[Thu Oct 17 13:59:33 2019] [Err]:     self.tk.call((self._w, 'coords') + args))]
[Thu Oct 17 13:59:33 2019] [Err]:   File "C:\Users\quint\Anaconda3\lib\site-packag[Thu Oct 17 13:59:33 2019] [Err]:     self.tk.call[Thu Oct[Thu Oct 17 13:59:33 2019] [Err]:   File "C:\Users\quint\Documents\GitHub\QplayBubbles-Releaes\lib\title.py", line 54, in <lambda>
[Thu Oct 17 13:59:33 2019] [Err]:     self.tk.call((self._w, 'coords') + args))]
[Thu Oct 17 13:59:33 2019] [Err]:     self._target(*self._args, **self._kwargs)
[Thu Oct 17 13:59:33 2019] [Err]:     self.tk.call((self._w, 'coords') + args))]
[Thu Oct 17 13:59:33 2019] [Err]:   File "C:\Users\quint\Anaconda3\lib\tkinter\__init__.py", line 2469, in coords
[Thu Oct 17 13:59:33 2019] [Err]:     self.tk.call((self._w, 'coords') + args))]
[Thu Oct 17 13:59:33 2019] [Err]:     self._target(*self._args, **self._kwargs)
[Thu Oct 17 13:59:33 2019] [Err]:   File "C:\Users\quint\Documents\GitHub\QplayBubbles-Releaes\lib\title.py", line 54, in <lambda>
[Thu Oct 17 13:59:33 2019] [Err]:     self._target(*self._args, **self._kwargs)
[Thu Oct 17 13:59:33 2019] [Err]:     self._target(*self._args, **self._kwargs)
[Thu Oct 17 13:59:33 2019] [Err]:     self.tk.call((self._w, 'coords') + args))]
[Thu Oct 17 13:59:33 2019] [Err]:   File "C:\Users\quint\Anaconda3\lib\site-packages\threadsafe_tkinter\__init__.py", line 71, in <lambda>
[Thu Oct 17 13:59:33 2019] [Err]:   File "C:\Users\quint\Documents\GitHub\QplayBubbles-Releaes\lib\title.py", line 53, in <lambda>
[Thu Oct 17 13:59:33 2019] [Err]:     self.tk.call((self._w, 'coords') + args))]
[Thu Oct 17 13:59:33 2019] [Err]:   File "C:\Users\quint\Documents\GitHub\QplayBubbles-Releaes\lib\title.py", line 54, in <lambda>
[Thu Oct 17 13:59:33 2019] [Err]:   File "C:\Users\quint\Documents\GitHub\QplayBubbles-Releaes\lib\title.py", line 54, in <lambda>
[Thu Oct 17 13:59:33 2019] [Err]:   File "C:\Users\quint\Anaconda3\lib\site-packages\threadsafe_tkinter\__init__.py", line 71, in <lambda>
[Thu Oct 17 13:59:33 2019] [Err]:   File "C:\Users\quint\Documents\GitHub\QplayBubbles-Releaes\lib\title.py", line 54, in <lambda>
[Thu Oct 17 13:59:33 2019] [Err]:   File "C:\Users\quint\Documents\GitHub\QplayBubbles-Releaes\lib\title.py", line 102, in create_bubble
[Thu Oct 17 13:59:33 2019] [Err]:   File "C:\Users\quint\Anaconda3\lib\site-packages\threadsafe_tkinter\__init__.py", line 71, in <lambda>
[Thu Oct 17 13:59:33 2019] [Err]:   File "C:\Users\quint\Anaconda3\lib\tkinter\__init__.py", line 2469, in coords
[Thu Oct 17 13:59:33 2019] [Err]:   File "C:\Users\quint\Anaconda3\lib\tkinter\__init__.py", line 2469, in coords
[Thu Oct 17 13:59:33 2019] [Err]:   Fi[Thu Oct 17 13:59:33 2019] [Err]:     self.tk.call((self._w, 'coords') + args))]
ne 71, in <lambda>
[Thu Oct 17 13:59:33 2019] [Err]:   File "C:\Users\quint\Anaconda3\lib\site-packages\threadsafe_tkinter\__init__.py", line 71, in <lambda>
[Thu Oct 17 13:59:33 2019] [Err]:   File "C:\Users\quint\Anaconda3\lib\site-packages\threadsafe_tkinter\__init__.py", line 71, in <lambda>
[Thu Oct 17 13:59:33 2019] [Err]:     self._target(*self._args, **self._kwargs)
[Thu Oct 17 13:59:33 2019] [Err]:   File "C:\Users\quint\Anaconda3\lib\site-packages\threadsafe_tkinter\__init__.py", line 71, in <lambda>
[Thu Oct 17 13:59:33 2019] [Err]:   File "C:\Users\quint\Documents\GitHub\QplayBubbles-Releaes\lib\title.py", line 53, in <lambda>
[Thu Oct 17 13:59:33 2019] [Err]:   File "C:\Users\quint\Anaconda3\lib\site-packages\threadsafe_tkinter\__init__.py", line 71, in <lambda>
[Thu Oct 17 13:59:33 2019] [Err]:   File "C:\Users\quint\Anaconda3\lib\site-packages\threadsafe_tkinter\__init__.py", line 71, in <lambda>
[Thu Oct 17 13:59:33 2019] [Err]:     self.tk.call((self._w, 'coords') + args))]
[Thu Oct 17 13:59:33 2019] [Err]:   File "C:\Users\quint\Anaconda3\lib\site-packages\threadsafe_tkinter\__init__.py", line 71, in <lambda>
[Thu Oct 17 13:59:33 2019] [Err]:     self.tk.call((self._w, 'coords') + args))]
[Thu Oct 17 13:59:33 2019] [Err]:   File "C:\Users\quint\Anaconda3\lib\site-packages\threadsafe_tkinter\__init__.py", line 71, in <lambda>
[Thu Oct 17 13:59:33 2019] [Err]:     Thread(None, lambda: self.background.move_bubbles()).start()
[Thu Oct 17 13:59:33 2019] [Err]:     self.tk.call((self._w, 'coords') + args))]
bbles()).start()
i[Thu Oct 17 13:59:33 2019] [Err]:   File "C:\Users\quint\Anaconda3\lib\site-packages\threadsafe_tkinter\__init__.py", line 71, in <lambda>
[Thu Oct 17 13:59:33 2019] [Err]:     self.call_tk_attr_threadsafe(_f, *a, **kw))
[Thu Oct 17 13:59:33 2019] [Err]:     Thread(None, lambda: self.background.move_bubbles()).start()
[Thu Oct 17 13:59:33 2019] [Err]:   File "C:\Users\quint\Anaconda3\lib\site-packages\threadsafe_tkinter\__init__.py", line 71, in <lambda>
[Thu Oct 17 13:59:33 2019] [Err]:   File "C:\Users\quint\Anaconda3\lib\site-packages\threadsafe_tkinter\__init__.py", line 71, in <lambda>
[Thu Oct 17 13:59:33 2019] [Err]:     Thread(None, lambda: self.background.move_bubbles()).start()
[Thu Oct 17 13:59:33 2019] [Err]:     Thread(None, lambda: self.background.create_bubble()).start()
[Thu Oct 17 13:59:33 2019] [Err]:     Thread(None, lambda: self.background.move_bubbles()).start()
[Thu Oct 17 13:59:33 2019] [Err]:     self.call_tk_attr_threadsafe(_f, *a, **kw))
[Thu Oct 17 13:59:33 2019] [Err]:   File "C:\Users\quint\Documents\GitHub\QplayBubbles-Releaes\lib\title.py", line 54, in <lambda>
[Thu Oct 17 13:59:33 2019] [Err]:   File "C:\Users\quint\Documents\GitHub\QplayBubbles-Releaes\lib\title.py", line 54, in <lambda>
[Thu Oct 17 13:59:33 2019] [Err]:   File "C:\Users\quint\Anaconda3\lib\site-packages\threadsafe_tkinter\__init__.py", line 71, in <lambda>
[Thu Oct 17 13:59:33 2019] [Err]:     Thread(None, lambda: self.background.move_bubbles()).start()
[Thu Oct 17 13:59:33 2019] [Err]:   File "C:\Users\quint\Documents\GitHub\QplayBubbles-Releaes\lib\title.py", line 54, in <lambda>
[Thu Oct 17 13:59:33 2019] [Err]:     self.__bubbles.append(self._canvas.create_oval(x - r, y - r, x + r, y + r, outline="white"))
[Thu Oct 17 13:59:33 2019] [Err]:     Thread(None, lambda: self.background.move_bub[Thu Oct 17 13:59:33 2019] [Err]:     self.call_tk_attr_threadsafe(_f, *[Thu Oct 17[Thu Oct 17 13:59:33 2019] [Err]:   File "C:\Users\quint\Documents\GitHub\QplayBubbles-Releaes\lib\title.py", line 126, in move_bubbles
[Thu Oct 17 13:59:33 2019] [Err]:     self.call_tk_attr_threadsafe(_f, *a, **kw))
[Thu Oct 17 13:59:33 2019] [Err]:     self.call_tk_attr_threadsafe(_f, *a, **kw))
[Thu Oct 17 13:59:33 2019] [Err]:     self.call_tk_attr_threadsafe(_f, *a, **kw))
[Thu Oct 17 13:59:33 2019] [Err]:   File "C:\Users\quint\Anaconda3\lib\site-packages\threadsafe_tkinter\__init__.py", line 71, in <lambda>
[Thu Oct 17 13:59:33 2019] [Err]:     self.call_tk_attr_threadsafe(_f, *a, **kw))
[Thu Oct 17 13:59:33 2019] [Err]:     self.call_tk_attr_threadsafe(_f, *a, **kw))
[Thu Oct 17 13:59:33 2019] [Err]:   File "C:\Users\quint\Documents\GitHub\QplayBubbles-Releaes\lib\title.py", line 126, in move_bubbles
[Thu Oct 17 13:59:33 2019] [Err]:   File "C:\Users\quint\Documents\GitHub\QplayBubbles-Releaes\lib\title.py", line 126, in move_bubbles
[Thu Oct 17 13:59:33 2019] [Err]:   File "C:\Users\quint\Documents\GitHub\QplayBubbles-Releaes\lib\title.py", line 98, in create_bubble
[Thu Oct 17 13:59:33 2019] [Err]:   File "C:\Users\quint\Documents\GitHub\QplayBubbles-Releaes\lib\title.py", line 126, in move_bubbles
[Thu Oct 17 13:59:33 2019] [Err]:   File "C:\Users\quint\Anaconda3\lib\site-packages\threadsafe_tkinter\__init__.py", line 88, in call_tk_attr_threadsafe
[Thu Oct 17 13:59:33 2019] [Err]:   File "C:\Users\quint\Anaconda3\lib\site-packages\threadsafe_tkinter\__init__.py", line 88, in call_tk_attr_threadsafe
[Thu Oct 17 13:59:33 2019] [Err]:     self.call_tk_attr_threadsafe(_f, *a, **kw))
[Thu Oct 17 13:59:33 2019] [Err]:     Thread(None, lambda: self.background.create_bubble()).start()
[Thu Oct 17 13:59:33 2019] [Err]:   File "C:\Users\quint\Anaconda3\lib\tkinter\__init__.py", line 2495, in create_oval
in move_bubbles
>
[Thu Oct 17 13:59:33 2019] [Err]:     self.call_tk_attr_threadsafe(_f, *a, **kw))
[Thu Oct 17 13:59:33 2019] [Err]:   File "C:\Users\quint\Anaconda3\lib\site-packages\threadsafe_tkinter\__init__.py", line 71, in <lambda>
[Thu Oct 17 13:59:33 2019] [Err]:     Thread(None, lambda: self.background.move_bubbles()).start()
[Thu Oct 17 13:59:33 2019] [Err]:     self.call_tk_attr_threadsafe(_f, *a, **kw))
[Thu Oct 17 13:59:33 2019] [Err]:   File "C:\Users\quint\Anaconda3\lib\site-packages\threadsafe_tkinter\__init__.py", line 88, in call_tk_attr_threadsafe
[Thu Oct 17 13:59:33 2019] [Err]:     self.call_tk_attr_threadsafe(_f, *a, **kw))
[Thu Oct 17 13:59:33 2019] [Err]:   File "C:\Users\quint\Anaconda3\lib\site-packages\threadsafe_tkinter\__init__.py", line 88, in call_tk_attr_threadsafe
[Thu Oct 17 13:59:33 2019] [Err]:   File "C:\Users\quint\Documents\GitHub\QplayBubbles-Releaes\lib\title.py", line 126, in move_bubbles
[Thu Oct 17 13:59:33 2019] [Err]:   File "C:\Users\quint\Documents\GitHub\QplayBubbles-Releaes\lib\title.py", line 126, in move_bubbles
[Thu Oct 17 13:59:33 2019] [Err]:     self.call_tk_attr_threadsafe(_f, *a, **kw))
[Thu Oct 17 13:59:33 2019] [Err]:     Thread(None, lambda: self.background.move_bubbles()).start()
[Thu Oct 17 13:59:33 2019] [Err]:     Thread(None, lambda: self.background.move_bubbles()).start()
[Thu Oct 17 13:59:33 2019] [Err]:   File "C:\Users\quint\Anaconda3\lib\site-packages\threadsafe_tkinter\__init__.py", line 88, in call_tk_attr_threadsafe
[Thu Oct 17 13:59:33 2019] [Err]:   File "C:\Users\quint\Anaconda3\lib\site-packages\threadsafe_tkinter\__init__.py", line 71, in <lambda>
[Thu Oct 17 13:59:33 2019] [Err]:   File "C:\Users\quint\Documents\GitHub\QplayBubbles-Releaes\lib\title.py", line 126, in move_bubbles
[Thu Oct 17 13:59:33 2019] [Err]:     self.call_tk_attr_threadsafe(_f, *a, **kw))
[Thu Oct 17 13:59:33 2019] [Err]:   File "C:\Users\quint\Documents\GitHub\QplayBubbles-Releaes\lib\title.py", line 126, in move_bubbles
[Thu Oct 17 13:59:33 2019] [Err]:   File "C:\Users\quint\Documents\GitHub\QplayBubbles-Releaes\lib\title.py", line 126, in move_bubbles
[Thu Oct 17 13:59:33 2019] [Err]:   File "C:\Users\quint\Documents\GitHub\QplayBubbles-Releaes\lib\title.py", line 102, in create_bubble
[Thu Oct 17 13:59:33 2019] [Err]:   File "C:\Users\quint\Documents\GitHub\QplayBubbles-Releaes\lib\title.py", line 98, in create_bubble
[Thu Oct 17 13:59:33 2019] [Err]:   File "C:\Users\quint\Documents\GitHub\QplayBubbles-Releaes\lib\title.py", line 98, in create_bubble
[Thu Oct 17 13:59:33 2019] [Err]:     Thread(None, lambda: self.background.move_bubbles()).start()
[Thu Oct 17 13:59:33 2019] [Err]:     self._canvas.move(self.__bubbles[index], -self.__speed[index], 0)
_init__.py", line 88, in call_tk_attr_threadsafe
[Thu Oct 17 13:59:33 2019] [Err]:     self._canvas.move(self.__bubbles[index], -self.__speed[index], 0)
[Thu Oct 17 13:59:33 2019] [Err]:   File "C:\Users\quint\Anaconda3\lib\site-packages\threadsafe_tkinter\__init__.py", line 88, in call_tk_attr_threadsafe
[Thu Oct 17 13:59:33 2019] [Err]:     raise result
[Thu Oct 17 13:59:33 2019] [Err]:   File "C:\Users\quint\Anaconda3\lib\site-packages\threadsafe_tkinter\__init__.py", line 88, in call_tk_attr_threadsafe
[Thu Oct 17 13:59:33 2019] [Err]:     self.call_tk_attr_threadsafe(_f, *a, **kw))
[Thu Oct 17 13:59:33 2019] [Err]:   File "C:\Users\quint\Anaconda3\lib\site-packages\threadsafe_tkinter\__init__.py", line 88, in call_tk_attr_threadsafe
[Thu Oct 17 13:59:33 2019] [Err]:   File "C:\Users\quint\Anaconda3\lib\site-packages\threadsafe_tkinter\__init__.py", line 88, in call_tk_attr_threadsafe
[Thu Oct 17 13:59:33 2019] [Err]:   File "C:\Users\quint\Anaconda3\lib\site-packages\threadsafe_tkinter\__init__.py", line 88, in call_tk_attr_threadsafe
[Thu Oct 17 13:59:33 2019] [Err]:     raise result
[Thu Oct 17 13:59:33 2019] [Err]:   File "C:\Users\quint\Documents\GitHub\QplayBubbles-Releaes\lib\title.py", line 126, in move_bubbles
[Thu Oct 17 13:59:33 2019] [Err]:   File "C:\Users\quint\Documents\GitHub\QplayBubbles-Releaes\lib\title.py", line 126, in move_bubbles
[Thu Oct 17 13:59:33 2019] [Err]:     self.call_tk_attr_threadsafe(_f, *a, **kw))
[Thu Oct 17 13:59:33 2019] [Err]:   File "C:\Users\quint\Anaconda3\lib\site-packages\threadsafe_tkinter\__init__.py", line 88, in call_tk_attr_threadsafe
[Thu Oct 17 13:59:33 2019] [Err]:   File "C:\Users\quint\Anaconda3\lib\site-packages\threadsafe_tkinter\__init__.py", line 88, in call_tk_attr_threadsafe
[Thu Oct 17 13:59:33 2019] [Err]:     y = randint(int(r), int(self._canvas.winfo_height() - r))
[Thu Oct 17 13:59:33 2019] [Err]:     self._canvas.move(self.__bubbles[index], -self.__speed[index], 0)
_init__.py", line 88, in call_tk_attr_threadsafe
[Thu Oct 17 13:59:33 2019] [Err]:   File "C:\Users\quint\Anaconda3\lib\site-packages\threadsafe_tkinter\__init__.py", line 88, in call_tk_attr_threadsafe
[Thu Oct 17 13:59:33 2019] [Err]:     self.call_tk_attr_threadsafe(_f, *a, **kw))
[Thu Oct 17 13:59:33 2019] [Err]:     self.__bubbles.append(self._canvas.create_oval(x - r, y - r, x + r, y + r, outline="white"))
[Thu Oct 17 13:59:33 2019] [Err]:     raise result
[Thu Oct 17 13:59:33 2019] [Err]:   File "C:\Users\quint\Anaconda3\lib\site-packages\threadsafe_tkinter\__init__.py", line 88, in call_tk_attr_threadsafe
[Thu Oct 17 13:59:33 2019] [Err]:   File "C:\Users\quint\Documents\GitHub\QplayBubbles-Releaes\lib\title.py", line 126, in move_bubbles
[Thu Oct 17 13:59:33 2019] [Err]:     y = randint(int(r), int(self._canvas.winfo_height() - r))
[Thu Oct 17 13:59:33 2019] [Err]:   File "C:\Users\quint\Anaconda3\lib\site-packages\threadsafe_tkinter\__init__.py", line 88, in call_tk_attr_threadsafe
[Thu Oct 17 13:59:33 2019] [Err]:   File "C:\Users\quint\Anaconda3\lib\site-packages\threadsafe_tkinter\__init__.py", line 88, in call_tk_attr_threadsafe
[Thu Oct 17 13:59:33 2019] [Err]:     self._canvas.move(self.__bubbles[index], -self.__speed[index], 0)
[Thu Oct 17 13:59:33 2019] [Err]:   File "C:\Users\quint\Documents\GitHub\QplayBubbles-Releaes\lib\title.py", line 126, in move_bubbles
[Thu Oct 17 13:59:33 2019] [Err]:   File "C:\Users\quint\Anaconda3\lib\site-packages\threadsafe_tkinter\__init__.py", line 88, in call_tk_attr_threadsafe
[Thu Oct 17 13:59:33 2019] [Err]:   File "C:\Users\quint\Anaconda3\lib\site-packages\threadsafe_tkinter\__init__.py", line 88, in call_tk_attr_threadsafe
[Thu Oct 17 13:59:33 2019] [Err]:     raise result
[Thu Oct 17 13:59:33 2019] [Err]:     return self._create('oval', args, kw)
[Thu Oct 17 13:59:33 2019] [Err]:     self._canvas.move(self.__bubbles[index], -self.__speed[index], 0)
[Thu Oct 17 13:59:33 2019] [Err]:   File "C:\Users\quint\Anaconda3\lib\tkinter\__init__.py", line 1000, i[Thu Oct 17 13:59:33 2019] [Err]:     raise result[Thu Oct 17 13:59:33 2019] [Err]:     self._canvas.move(self.__bubbles[index], -self.__speed[index], 0)
[Thu Oct 17 13:59:33 2019] [Err]:   File "C:\Users\quint\Anaconda3\lib\site-packages\threadsafe_tkinter\__init__.py", line 133, in process_requests
[Thu Oct 17 13:59:33 2019] [Err]:     self._canvas.move(self.__bubbles[index], -self.__speed[index], 0)
[Thu Oct 17 13:59:33 2019] [Err]:     raise result
[Thu Oct 17 13:59:33 2019] [Err]:     self._canvas.move(self.__bubbles[index], -self.__speed[index], 0)
[Thu Oct 17 13:59:33 2019] [Err]:     raise result
[Thu Oct 17 13:59:33 2019] [Err]:   File "C:\Users\quint\Anaconda3\lib\site-packages\threadsafe_tkinter\__init__.py", line 133, in process_requests
[Thu Oct 17 13:59:33 2019] [Err]:   File "C:\Users\quint\Anaconda3\lib\tkinter\__init__.py", line 2591, in move
[Thu Oct 17 13:59:33 2019] [Err]:   File "C:\Users\quint\Anaconda3\lib\tkinter\__init__.py", line 2591, in move
[Thu Oct 17 13:59:33 2019] [Err]:   File "C:\Users\quint\Documents\GitHub\QplayBubbles-Releaes\lib\title.py", line 126, in move_bubbles
[Thu Oct 17 13:59:33 2019] [Err]:   File "C:\Users\quint\Anaconda3\lib\site-packages\threadsafe_tkinter\__init__.py", line 88, in call_tk_attr_threadsafe
[Thu Oct 17 13:59:33 2019] [Err]:   File "C:\Users\quint\Anaconda3\lib\site-packages\threadsafe_tkinter\__init__.py", line 133, in process_requests
[Thu Oct 17 13:59:33 2019] [Err]:     self._canvas.move(self.__bubbles[index], -self.__speed[index], 0)
_init__.py", line 133, in process_requests
safe
[Thu Oct 17 13:59:33 2019] [Err]:     self.tk.call((self._w, 'move') + args)
[Thu Oct 17 13:59:33 2019] [Err]:   File "C:\Users\quint\Anaconda3\lib\site-packages\threadsafe_tkinter\__init__.py", line 88, in call_tk_attr_threadsafe
[Thu Oct 17 13:59:33 2019] [Err]:   File "C:\Users\quint\Anaconda3\lib\tkinter\__init__.py", line 1000, in winfo_height
[Thu Oct 17 13:59:33 2019] [Err]:     raise result
[Thu Oct 17 13:59:33 2019] [Err]:   File "C:\Users\quint\Anaconda3\lib\tkinter\__init__.py", line 2591, in move
[Thu Oct 17 13:59:33 2019] [Err]:   File "C:\Users\quint\Anaconda3\lib\site-packages\threadsafe_tkinter\__init__.py", line 88, in call_tk_attr_threadsafe
[Thu Oct 17 13:59:33 2019] [Err]:     raise result
[Thu Oct 17 13:59:33 2019] [Err]:   File "C:\Users\quint\Anaconda3\lib\tkinter\__init__.py", line 2591, in move
[Thu Oct 17 13:59:33 2019] [Err]:     raise result
[Thu Oct 17 13:59:33 2019] [Err]:   File "C:\Users\quint\Anaconda3\lib\tkinter\__init__.py", line 2495, in create_oval
[Thu Oct 17 13:59:33 2019] [Err]:     raise result
[Thu Oct 17 13:59:33 2019] [Err]:   File "C:\Users\quint\Anaconda3\lib\site-packages\threadsafe_tkinter\__init__.py", line 133, in process_requests
[Thu Oct 17 13:59:33 2019] [Err]:   File "C:\Users\quint\Anaconda3\lib\tkinter\__init__.py", line 2591, in move
[Thu Oct 17 13:59:33 2019] [Err]:     raise result
[Thu Oct 17 13:59:33 2019] [Err]:   File "C:\Users\quint\Anaconda3\lib\tkinter\__init__.py", line 2591, in move
[Thu Oct 17 13:59:33 2019] [Err]:     self._canvas.move(self.__bubbles[index], -self.__speed[index], 0)
[Thu Oct 17 13:59:33 2019] [Err]:     self.tk.call((self._w, 'move') + args)
[Thu Oct 17 13:59:33 2019] [Err]:   File "C:\Users\quint\Anaconda3\lib\site-packages\threadsafe_tkinter\__init__.py", line 133, in process_requests
[Thu Oct 17 13:59:33 2019] [Err]:     response[:] = (func(*a, **kw), False)
ackages\threadsafe_tkinter\__init__.py", line 133, in process_requests
[Thu Oct 17 13:59:33 2019] [Err]:     response[:] = (func(*a, **kw), False)
[Thu Oct 17 13:59:33 2019] [Err]:   File "C:\Users\quint\Anaconda3\lib\site-packages\threadsafe_tkinter\__init__.py", line 133, in process_requests
[Thu Oct 17 13:59:33 2019] [Err]:     self.tk.call('winfo', 'height', self._w))
[Thu Oct 17 13:59:33 2019] [Err]:   File "C:\Users\quint\Anaconda3\lib\site-packages\threadsafe_tkinter\__init__.py", line 133, in process_requests
[Thu Oct 17 13:59:33 2019] [Err]:   File "C:\Users\quint\Anaconda3\lib\tkinter\__init__.py", line 2591, in move
[Thu Oct 17 13:59:33 2019] [Err]:     self.tk.call((self._w, 'move') + args)
[Thu Oct 17 13:59:33 2019] [Err]:     self.tk.call((self._w, 'move') + args)
[Thu Oct 17 13:59:33 2019] [Err]:   File "C:\Users\quint\Anaconda3\lib\site-packages\threadsafe_tkinter\__init__.py", line 133, in process_requests
[Thu Oct 17 13:59:33 2019] [Err]:   File "C:\Users\quint\Anaconda3\lib\site-packages\threadsafe_tkinter\__init__.py", line 133, in process_requests
[Thu Oct 17 13:59:33 2019] [Err]:   File "C:\Users\quint\Anaconda3\lib\tkinter\__init__.py", line 2591, in move
[Thu Oct 17 13:59:33 2019] [Err]:   File "C:\Users\quint\Anaconda3\lib\site-packages\threadsafe_tkinter\__init__.py", line 133, in process_requests
[Thu Oct 17 13:59:33 2019] [Err]:   File "C:\Users\quint\Anaconda3\lib\site-packages\threadsafe_tkinter\__init__.py", line 133, in process_requests
[Thu Oct 17 13:59:33 2019] [Err]:     self._canvas.move(self.__bubbles[index], -self.__speed[index], 0)
[Thu Oct 17 13:59:33 2019] [Err]:   File "C:\Users\quint\Anaconda3\lib\site-packages\threadsafe_tkinter\__init__.py", line 133, in process_requests
[Thu Oct 17 13:59:33 2019] [Err]:   File "C:\Users\quint\Anaconda3\lib\site-packages\threadsafe_tkinter\__init__.py", line 71, in <lambda>
[Thu Oct 17 13:59:33 2019] [Err]:     raise result
[Thu Oct 17 13:59:33 2019] [Err]:     self.tk.call((self._w, 'move') + args)
[Thu Oct 17 13:59:33 2019] [Err]:     self.tk.call('winfo', 'height', self._w))
[Thu Oct 17 13:59:33 2019] [Err]:     raise result
[Thu Oct 17 13:59:33 2019] [Err]:     response[:] = (func(*a, **kw), False)
[Thu Oct 17 13:59:33 2019] [Err]:     self.tk.call((self._w, 'move') + args)
[Thu Oct 17 13:59:33 2019] [Err]:     response[:] = (func(*a, **kw), False)
[Thu Oct 17 13:59:33 2019] [Err]:     response[:] = (func(*a, **kw), False)
[Thu Oct 17 13:59:33 2019] [Err]:     self.tk.call((self._w, 'move') + args)
ckages\threadsafe_tkinter\__init__.py", line 71, in <lambda>
equests
[Thu Oct 17 13:59:33 2019] [Err]:     response[:] = (func(*a, **kw), False)
ackages\threadsafe_tkinter\__init__.[Thu Oct 17 13:59:33 2019] [Err]:   File "C:\Users\quint\Anaconda3\lib\tkinter\__init__.py", line 2591, in move
[Thu Oct 17 13:59:33 2019] [Err]: _tkinter.TclError: invalid command name ".!canvas"
[Thu Oct 17 13:59:33 2019] [Err]:     raise result
[Thu Oct 17 13:59:33 2019] [Err]:     self.tk.call((self._w, 'move') + args)
[Thu Oct 17 13:59:33 2019] [Err]:   File "C:\Users\quint\Anaconda3\lib\site-packages\threadsafe_tkinter\__init__.py", line 133, in process_requests
[Thu Oct 17 13:59:33 2019] [Err]:     return self._create('oval', args, kw)
[Thu Oct 17 13:59:33 2019] [Err]:   File "C:\Users\quint\Anaconda3\lib\site-packages\threadsafe_tkinter\__init__.py", line 133, in process_requests
[Thu Oct 17 13:59:33 2019] [Err]:     self.tk.call((self._w, 'move') + args)
[Thu Oct 17 13:59:33 2019] [Err]:     response[:] = (func(*a, **kw), False)
[Thu Oct 17 13:59:33 2019] [Err]:   File "C:\Users\quint\Anaconda3\lib\site-packages\threadsafe_tkinter\__init__.py", line 133, in process_requests
[Thu Oct 17 13:59:33 2019] [Err]:   File "C:\Users\quint\Anaconda3\lib\tkinter\__init__.py", line 2591, in move
[Thu Oct 17 13:59:33 2019] [Err]: _tkinter.TclError: invalid command name ".!canvas"
[Thu Oct 17 13:59:34 2019] [Err]:     response[:] = (func(*a, **kw), False)
ackages\threadsafe_tkinter\__init__.py", line 133, in process_requests
[Thu Oct 17 13:59:34 2019] [Err]:     self.tk.call((self._w, 'move') + args)
[Thu Oct 17 13:59:34 2019] [Err]:   File "C:\Users\quint\Anaconda3\lib\site-packages\threadsafe_tkinter\__init__.py", line 71, in <lambda>
[Thu Oct 17 13:59:34 2019] [Err]:   File "C:\Users\quint\Anaconda3\lib\site-packages\threadsafe_tkinter\__init__.py", line 133, in process_requests
[Thu Oct 17 13:59:34 2019] [Err]:     self.call_tk_attr_threadsafe(_f, *a, **kw))
[Thu Oct 17 13:59:34 2019] [Err]: _tkinter.TclError: invalid command name ".!canvas"
[Thu Oct 17 13:59:34 2019] [Err]: _tkinter.TclError: invalid command name ".!canvas"
[Thu Oct 17 13:59:34 2019] [Err]:     self.tk.call((self._w, 'move') + args)
[Thu Oct 17 13:59:34 2019] [Err]:   File "C:\Users\quint\Anaconda3\lib\site-packages\threadsafe_tkinter\__init__.py", line 71, in <lambda>
[Thu Oct 17 13:59:34 2019] [Err]:     self.tk.call((self._w, 'move') + args)
[Thu Oct 17 13:59:34 2019] [Err]:   File "C:\Users\quint\Anaconda3\lib\site-packages\threadsafe_tkinter\__init__.py", line 71, in <lambda>
[Thu Oct 17 13:59:34 2019] [Err]: 
[Thu Oct 17 13:59:34 2019] [Err]: _tkinter.TclError: invalid command name ".!canvas"
[Thu Oct 17 13:59:34 2019] [Err]:   File "C:\Users\quint\Anaconda3\lib\site-packages\threadsafe_tkinter\__init__.py", line 71, in <lambda>
[Thu Oct 17 13:59:34 2019] [Err]:   File "C:\Users\quint\Anaconda3\lib\site-packages\threadsafe_tkinter\__init__.py", line 71, in <lambda>
[Thu Oct 17 13:59:34 2019] [Err]:     response[:] = (func(*a, **kw), False)
[Thu Oct 17 13:59:34 2019] [Err]:   File "C:\Users\quint\Anaconda3\lib\site-packages\threadsafe_tkinter\__init__.py", line 71, in <lambda>
[Thu Oct 17 13:59:34 2019] [Err]:   File "C:\Users\quint\Anaconda3\lib\tkinter\__init__.py", line 2591, in move
[Thu Oct 17 13:59:34 2019] [Err]: _tkinter.TclError: invalid command name ".!canvas"
hreadsafe_tkinter\__init__.py", line 133, in process_requests
[Thu Oct 17 13:59:34 2019] [Err]:   File "C:\Users\quint\Anaconda3\lib\site-packages\threadsafe_tkinter\__init__.py", line 133, in process_requests
[Thu Oct 17 13:59:34 2019] [Err]:     response[:] = (func(*a, **kw), False)
[Thu Oct 17 13:59:34 2019] [Err]: 
[Thu Oct 17 13:59:34 2019] [Err]:     self.call_tk_attr_threadsafe(_f, *a, **kw))
[Thu Oct 17 13:59:34 2019] [Err]: _tkinter.TclError: invalid command name ".!canvas"
[Thu Oct 17 13:59:34 2019] [Err]:     self.call_tk_attr_threadsafe(_f, *a, **kw))
[Thu Oct 17 13:59:34 2019] [Err]:     self.tk.call((self._w, 'move') + args)
[Thu Oct 17 13:59:34 2019] [Err]:     response[:] = (func(*a, **kw), False)
[Thu Oct 17 13:59:34 2019] [Err]:     response[:] = (func(*a, **kw), False)
[Thu Oct 17 13:59:34 2019] [Err]:     response[:] = (func(*a, **kw), False)
[Thu Oct 17 13:59:34 2019] [Err]:   File "C:\Users\quint\Anaconda3\lib\site-packages\threadsafe_tkinter\__init__.py", line 71, in <lambda>
[Thu Oct 17 13:59:34 2019] [Err]:     response[:] = (func(*a, **kw), False)
[Thu Oct 17 13:59:34 2019] [Err]:   File "C:\Users\quint\Anaconda3\lib\site-packages\threadsafe_tkinter\__init__.py", line 71, in <lambda>
[Thu Oct 17 13:59:34 2019] [Err]:     self.tk.call((self._w, 'move') + args)
[Thu Oct 17 13:59:34 2019] [Err]:     response[:] = (func(*a, **kw), False)
[Thu Oct 17 13:59:34 2019] [Err]: _tkinter.TclError: invalid command name ".!canvas"
[Thu Oct 17 13:59:34 2019] [Err]:     self.tk.call((self._w, 'move') + args)
[Thu Oct 17 13:59:34 2019] [Err]:     self.call_tk_attr_threadsafe(_f, *a, **kw))
[Thu Oct 17 13:59:34 2019] [Err]:     response[:] = (func(*a, **kw), False)
[Thu Oct 17 13:59:34 2019] [Err]:     self.call_tk_attr_threadsafe(_f, *a, **kw))
[Thu Oct 17 13:59:34 2019] [Err]:     response[:] = (func(*a, **kw), False)
[Thu Oct 17 13:59:34 2019] [Err]:   File "C:\Users\quint\Anaconda3\lib\site-packages\threadsafe_tkinter\__init__.py", line 71, in <lambda>
[Thu Oct 17 13:59:34 2019] [Err]: _tkinter.TclError: invalid command name ".!canvas"
[Thu Oct 17 13:59:34 2019] [Err]:     self.call_tk_attr_threadsafe(_f, *a, **kw))
[Thu Oct 17 13:59:34 2019] [Err]:     response[:] = (func(*a, **kw), False)
kw))
s\t[Thu Oct 17 13:59:34 2019] [Err]:     self.call_tk_attr_threadsafe(_f, *a, **kw))
[Thu Oct 17 13:59:34 2019] [Err]:     self.call_tk_attr_threadsafe(_f, *a, **kw))
[Thu Oct 17 13:59:34 2019] [Err]: _tkinter.TclError: invalid command name ".!canvas"
[Thu Oct 17 13:59:34 2019] [Err]: During handling of the above exception, another exception occurred:
[Thu Oct 17 13:59:34 2019] [Err]: _tkinter.TclError: invalid command name ".!canvas"
[Thu Oct 17 13:59:34 2019] [Err]: _tkinter.TclError: invalid command name ".!canvas"
[Thu Oct 17 13:59:34 2019] [Err]:   File "C:\Users\quint\Anaconda3\lib\site-packages\threadsafe_tkinter\__init__.py", line 88, in call_tk_attr_threadsafe
[Thu Oct 17 13:59:34 2019] [Err]: _tkinter.TclError: invalid command name ".!canvas"
[Thu Oct 17 13:59:34 2019] [Err]: _tkinter.TclError: invalid command name ".!canvas"
hreadsafe_tkinter\__init__.py", line 88, in call_tk_attr_threadsafe
[Thu Oct 17 13:59:34 2019] [Err]: _tkinter.TclError: invalid command name ".!canvas"
[Thu Oct 17 13:59:34 2019] [Err]:   File "C:\Users\quint\Anaconda3\lib\site-packages\threadsafe_tkinter\__init__.py", line 88, in call_tk_attr_threadsafe
[Thu Oct 17 13:59:34 2019] [Err]: _tkinter.TclError: invalid command name ".!canvas"
[Thu Oct 17 13:59:34 2019] [Err]: _tkinter.TclError: invalid command name ".!canvas"
[Thu Oct 17 13:59:34 2019] [Err]:     response[:] = (func(*a, **kw), False)
[Thu Oct 17 13:59:34 2019] [Err]:   File "C:\Users\quint\Anaconda3\lib\site-packages\threadsafe_tkinter\__init__.py", line 88, in call_tk_attr_threadsafe
[Thu Oct 17 13:59:34 2019] [Err]: During handling of the above exception, another exception occurred:
[Thu Oct 17 13:59:34 2019] [Err]: During handling of the above exception, another exception occurred:
[Thu Oct 17 13:59:34 2019] [Err]: _tkinter.TclError: invalid command name ".!canvas"
[Thu Oct 17 13:59:34 2019] [Err]:   File "C:\Users\quint\Anaconda3\lib\site-packages\threadsafe_tkinter\__init__.py", line 71, in <lambda>
[Thu Oct 17 13:59:34 2019] [Err]:     self.call_tk_attr_threadsafe(_f, *a, **kw))
[Thu Oct 17 13:59:34 2019] [Err]: 
[Thu Oct 17 13:59:34 2019] [Err]:     raise result
[Thu Oct 17 13:59:34 2019] [Err]:   File "C:\Users\quint\Anaconda3\lib\site-packages\threadsafe_tkinter\__init__.py", line 71, in <lambda>
[Thu Oct 17 13:59:34 2019] [Err]:     self.call_tk_attr_threadsafe(_f, *a, **kw))
[Thu Oct 17 13:59:34 2019] [Err]: 
[Thu Oct 17 13:59:34 2019] [Err]: 
[Thu Oct 17 13:59:34 2019] [Err]: During handling of the above exception, another exception occurred:
[Thu Oct 17 13:59:34 2019] [Err]:     response[:] = (func(*a, **kw), False)
[Thu Oct 17 13:59:34 2019] [Err]:     response[:] = (func(*a, **kw), False)
[Thu Oct 17 13:59:34 2019] [Err]: _tkinter.TclError: invalid command name ".!canvas"
[Thu Oct 17 13:59:34 2019] [Err]: 
[Thu Oct 17 13:59:34 2019] [Err]:   File "C:\Users\quint\Anaconda3\lib\site-packages\threadsafe_tkinter\__init__.py", line 71, in <lambda>
[Thu Oct 17 13:59:34 2019] [Err]:     self.call_tk_attr_threadsafe(_f, *a, **kw))
[Thu Oct 17 13:59:34 2019] [Err]:   File "C:\Users\quint\Anaconda3\lib\site-packages\threadsafe_tkinter\__init__.py", line 88, in call_tk_attr_threadsafe
[Thu Oct 17 13:59:34 2019] [Err]:   File "C:\Users\quint\Anaconda3\lib\site-packages\threadsafe_tkinter\__init__.py", line 88, in call_tk_attr_threadsafe
[Thu Oct 17 13:59:34 2019] [Err]:     *(args + self._options(cnf, kw))))
[Thu Oct 17 13:59:34 2019] [Err]: 
[Thu Oct 17 13:59:34 2019] [Err]: 
ite-packages\threadsafe_tkinter\__init__.py", line 88, in call_tk_attr_threadsafe
[Thu Oct 17 13:59:34 2019] [Err]:     raise result
[Thu Oct 17 13:59:34 2019] [Err]:   File "C:\Users\quint\Anaconda3\lib\site-packages\threadsafe_tkinter\__init__.py", line 88, in call_tk_attr_threadsafe
[Thu Oct 17 13:59:34 2019] [Err]: 
[Thu Oct 17 13:59:34 2019] [Err]: During handling of the above exception, another exception occurred:
[Thu Oct 17 13:59:34 2019] [Err]: _tkinter.TclError: invalid command name ".!canvas"
[Thu Oct 17 13:59:34 2019] [Err]: 
[Thu Oct 17 13:59:34 2019] [Err]:   File "C:\Users\quint\Anaconda3\lib\site-packages\threadsafe_tkinter\__init__.py", line 88, in call_tk_attr_threadsafe
[Thu Oct 17 13:59:34 2019] [Err]:   [Thu Oct 17 13:59:34 2019] [Err]: 
a, **kw))
xception occurred:
\__init__.py", line 133, in process_requests
safe
[Thu Oct 17 13:59:34 2019] [Err]: 
kinter.TclError: invalid command name ".!canvas"
[Thu Oct 17 13:59:34 2019] [Err]: During handling of the above exception, another exception occurred:
[Thu Oct 17 13:59:34 2019] [Err]: During handling of the above exception, another exception occurred:
[Thu Oct 17 13:59:34 2019] [Err]:     raise result
[Thu Oct 17 13:59:34 2019] [Err]: During handling of the above exception, another exception occurred:
[Thu Oct 17 13:59:34 2019] [Err]: During handling of the above exception, another exception occurred:
[Thu Oct 17 13:59:34 2019] [Err]: 
[Thu Oct 17 13:59:34 2019] [Err]: 
[Thu Oct 17 13:59:34 2019] [Err]: _tkinter.TclError: invalid command name ".!canvas"
[Thu Oct 17 13:59:34 2019] [Err]:   File "C:\Users\quint\Anaconda3\lib\site-packages\threadsafe_tkinter\__init__.py", line 71, in <lambda>
[Thu Oct 17 13:59:34 2019] [Err]:     self.call_tk_attr_threadsafe(_f, *a, **kw))
[Thu Oct 17 13:59:34 2019] [Err]:   File "C:\Users\quint\Anaconda3\lib\site-packages\threadsafe_tkinter\__init__.py", line 88, in call_tk_attr_threadsafe
[Thu Oct 17 13:59:34 2019] [Err]: 
[Thu Oct 17 13:59:34 2019] [Err]: 
[Thu Oct 17 13:59:34 2019] [Err]:   File "C:\Users\quint\Anaconda3\lib\site-packages\threadsafe_tkinter\__init__.py", line 88, in call_tk_attr_threadsafe
[Thu Oct 17 13:59:34 2019] [Err]:   File "C:\Users\quint\Anaconda3\lib\site-packages\threadsafe_tkinter\__init__.py", line 88, in call_tk_attr_threadsafe
[Thu Oct 17 13:59:34 2019] [Err]:   File "C:\Users\quint\Anaconda3\lib\site-packages\threadsafe_tkinter\__init__.py", line 88, in call_tk_attr_threadsafe
[Thu Oct 17 13:59:34 2019] [Err]:     raise result
[Thu Oct 17 13:59:34 2019] [Err]:     self.call_tk_attr_threadsafe(_f, *a, **kw))
[Thu Oct 17 13:59:34 2019] [Err]: 
[Thu Oct 17 13:59:34 2019] [Err]:     raise result
ttr_threadsafe(_f, *a, **kw))
s\threadsafe_tkinter\__init__.py", line 133, in process_requests
safe
[Thu Oct 17 13:59:34 2019] [Err]:   File "C:\Users\quint\Anaconda3\lib\site-packages\threadsafe_tkinter\__init__.py", line 88, in call_tk_attr_threadsafe
[Thu Oct 17 13:59:34 2019] [Err]: During handling of the above exception, another exception occurred:
[Thu Oct 17 13:59:34 2019] [Err]:     raise result
 the above exception, another exception occurred:
\__init__.py", line 88, in call_tk_attr_threadsafe
[Thu Oct 17 13:59:34 2019] [Err]: 
[Thu Oct 17 13:59:34 2019] [Err]:   File "C:\Users\quint\Anaconda3\lib\site-packages\threadsafe_tkinter\__init__.py", line 133, in process_requests
[Thu Oct 17 13:59:34 2019] [Err]:     raise result
[Thu Oct 17 13:59:34 2019] [Err]: During handling of the above exception, another exception occurred:
[Thu Oct 17 13:59:34 2019] [Err]: During handling of the above exception, another exception occurred:
[Thu Oct 17 13:59:34 2019] [Err]: During handling of the above exception, another exception occurred:
[Thu Oct 17 13:59:34 2019] [Err]:     raise result
[Thu Oct 17 13:59:34 2019] [Err]:     raise result
[Thu Oct 17 13:59:34 2019] [Err]:     raise result
[Thu Oct 17 13:59:34 2019] [Err]:   File "C:\Users\quint\Anaconda3\lib\site-packages\threadsafe_tkinter\__init__.py", line 133, in process_requests
[Thu Oct 17 13:59:34 2019] [Err]: 
[Thu Oct 17 13:59:34 2019] [Err]: 
[Thu Oct 17 13:59:34 2019] [Err]:     self.call_tk_attr_threadsafe(_f, *a, **kw))
[Thu Oct 17 13:59:34 2019] [Err]: 
[Thu Oct 17 13:59:34 2019] [Err]: During handling of the above exception, another exception occurred:
[Thu Oct 17 13:59:34 2019] [Err]: 
[Thu Oct 17 13:59:34 2019] [Err]: During handling of the above exception, another exception occurred:
[Thu Oct 17 13:59:34 2019] [Err]:   File "C:\Users\quint\Anaconda3\lib\site-packages\threadsafe_tkinter\__init__.py", line 88, in call_tk_attr_threadsafe
[Thu Oct 17 13:59:34 2019] [Err]:   File "C:\Users\quint\Anaconda3\lib\site-packages\threadsafe_tkinter\__init__.py", line 88, in call_tk_attr_threadsafe
[Thu Oct 17 13:59:34 2019] [Err]: 
[Thu Oct 17 13:59:34 2019] [Err]:     response[:] = (func(*a, **kw), False)
[Thu Oct 17 13:59:34 2019] [Err]: Traceback (most recent call last):
[Thu Oct 17 13:59:34 2019] [Err]: Traceback (most recent call last):
[Thu Oct 17 13:59:34 2019] [Err]: During handling of the above exception, another exception occurred:
[Thu Oct 17 13:59:34 2019] [Err]:   File "C:\Users\quint\Anaconda3\lib\site-packages\threadsafe_tkinter\__init__.py", line 133, in process_requests
[Thu Oct 17 13:59:34 2019] [Err]: Traceback (most recent call last):
[Thu Oct 17 13:59:34 2019] [Err]: During handling of the above exception, another exception occurred:
[Thu Oct 17 13:59:34 2019] [Err]:   File "C:\Users\quint\Anaconda3\lib\site-packages\threadsafe_tkinter\__init__.py", line 133, in process_requests
[Thu Oct 17 13:59:34 2019] [Err]:     response[:] = (func(*a, **kw), False)
ing.py", line 917, in _bootstrap_inner
 line 88, in call_tk_attr_threadsafe
[Thu Oct 17 13:59:34 2019] [Err]: _tkinter.TclError: invalid command name ".!canvas"
[Thu Oct 17 13:59:34 2019] [Err]:   File "C:\Users\quint\Anaconda3\lib\site-packages\threadsafe_tkinter\__init__.py", line 133, in process_requests
[Thu Oct 17 13:59:34 2019] [Err]: 
[Thu Oct 17 13:59:34 2019] [Err]: Traceback (most recent call last):
[Thu Oct 17 13:59:34 2019] [Err]:   File "C:\Users\quint\Anaconda3\lib\site-packages\threadsafe_tkinter\__init__.py", line 133, in process_requests
[Thu Oct 17 13:59:34 2019] [Err]:   File "C:\Users\quint\Anaconda3\lib\threading.py", line 917, in _bootstrap_inner
[Thu Oct 17 13:59:34 2019] [Err]: 
[Thu Oct 17 13:59:34 2019] [Err]: 
[Thu Oct 17 13:59:34 2019] [Err]:   File "C:\Users\quint\Anaconda3\lib\site-packages\threadsafe_tkinter\__init__.py", line 133, in process_requests
[Thu Oct 17 13:59:34 2019] [Err]:     response[:] = (func(*a, **kw), False)
[Thu Oct 17 13:59:34 2019] [Err]: 
[Thu Oct 17 13:59:34 2019] [Err]:     response[:] = (func(*a, **kw), False)
[Thu Oct 17 13:59:34 2019] [Err]: 
[Thu Oct 17 13:59:34 2019] [Err]: 
[Thu Oct 17 13:59:34 2019] [Err]:     response[:] = (func(*a, **kw), False)
[Thu Oct 17 13:59:34 2019] [Err]: During handling of the above exception, another exception occurred:
[Thu Oct 17 13:59:34 2019] [Err]: During handling of the above exception, another exception occurred:
[Thu Oct 17 13:59:34 2019] [Err]: 
[Thu Oct 17 13:59:34 2019] [Err]: 
[Thu Oct 17 13:59:34 2019] [Err]:   File "C:\Users\quint\Anaconda3\lib\site-packages\threadsafe_tkinter\__init__.py", line 133, in process_requests
[Thu Oct 17 13:59:34 2019] [Err]:   File "C:\Users\quint\Anaconda3\lib\site-packages\threadsafe_tkinter\__init__.py", line 133, in process_requests
[Thu Oct 17 13:59:34 2019] [Err]: Traceback (most recent call last):
[Thu Oct 17 13:59:34 2019] [Err]:   File "C:\Users\quint\Anaconda3\lib\threading.py", line 917, in _bootstrap_inner
[Thu Oct 17 13:59:34 2019] [Err]: Traceback (most recent call last):
[Thu Oct 17 13:59:34 2019] [Err]:     raise result
[Thu Oct 17 13:59:34 2019] [Err]:     raise result
[Thu Oct 17 13:59:34 2019] [Err]: During handling of the above exception, another exception occurred:
[Thu Oct 17 13:59:34 2019] [Err]: 
[Thu Oct 17 13:59:34 2019] [Err]:     raise result
[Thu Oct 17 13:59:34 2019] [Err]:   File "C:\Users\quint\Anaconda3\lib\site-packages\threadsafe_tkinter\__init__.py", line 88, in call_tk_attr_threadsafe
[Thu Oct 17 13:59:34 2019] [Err]: 
[Thu Oct 17 13:59:34 2019] [Err]:     response[:] = (func(*a, **kw), False)
[Thu Oct 17 13:59:34 2019] [Err]: Traceback (most recent call last):
[Thu Oct 17 13:59:34 2019] [Err]:     response[:] = (func(*a, **kw), False)
[Thu Oct 17 13:59:34 2019] [Err]: 
[Thu Oct 17 13:59:34 2019] [Err]: Traceback (most recent call last):
[Thu Oct 17 13:59:34 2019] [Err]: Traceback (most recent call last):
[Thu Oct 17 13:59:34 2019] [Err]: Traceback (most recent call last):
alse)
ackages\threadsafe_tkinter\__init__.py", line 133, in process_requests
[Thu Oct 17 13:59:34 2019] [Err]: _tkinter.TclError: invalid command name ".!canvas"
[Thu Oct 17 13:59:34 2019] [Err]: Traceback (most recent call last):
[Thu Oct 17 13:59:34 2019] [Err]:   File "C:\Users\quint\Anaconda3\lib\site-packages\threadsafe_tkinter\__init__.py", line 133, in process_requests
[Thu Oct 17 13:59:34 2019] [Err]: 
[Thu Oct 17 13:59:34 2019] [Err]:     response[:] = (func(*a, **kw), False)
ackages\threadsafe_tkinter\__init__.py", line 133, in process_requests
[Thu Oct 17 13:59:34 2019] [Err]: Traceback (most recent call last):
[Thu Oct 17 13:59:34 2019] [Err]:   File "C:\Users\quint\Anaconda3\lib\threading.py", line 917, in _bootstrap_inner
[Thu Oct 17 13:59:34 2019] [Err]: Traceback (most recent call last):
[Thu Oct 17 13:59:34 2019] [Err]: Traceback (most recent call last):
[Thu Oct 17 13:59:34 2019] [Err]:     self.run()
[Thu Oct 17 13:59:34 2019] [Err]: Traceback (most recent call last):
[Thu Oct 17 13:59:34 2019] [Err]: Traceback (most recent call last):
[Thu Oct 17 13:59:34 2019] [Err]:     response[:] = (func(*a, **kw), False)
[Thu Oct 17 13:59:34 2019] [Err]: _tkinter.TclError: invalid command name ".!canvas"
[Thu Oct 17 13:59:34 2019] [Err]: _tkinter.TclError: invalid command name ".!canvas"
[Thu Oct 17 13:59:34 2019] [Err]: 
[Thu Oct 17 13:59:34 2019] [Err]:   File "C:\Users\quint\Anaconda3\lib\site-packages\threadsafe_tkinter\__init__.py", line 133, in process_requests
[Thu Oct 17 13:59:34 2019] [Err]:   File "C:\Users\quint\Anaconda3\lib\threading.py", line 917, in _bootstrap_inner
[Thu Oct 17 13:59:34 2019] [Err]:   File "C:\Users\quint\Anaconda3\lib\threading.py", line 917, in _bootstrap_inner
[Thu Oct 17 13:59:34 2019] [Err]:     self.run()
[Thu Oct 17 13:59:34 2019] [Err]: 
[Thu Oct 17 13:59:34 2019] [Err]: _tkinter.TclError: invalid command name ".!canvas"
[Thu Oct 17 13:59:34 2019] [Err]:   File "C:\Users\quint\Anaconda3\lib\site-packages\threadsafe_tkinter\__init__.py", line 133, in process_requests
[Thu Oct 17 13:59:34 2019] [Err]:     response[:] = (func(*a, **kw), False)
[Thu Oct 17 13:59:34 2019] [Err]: _tkinter.TclError: invalid command name ".!canvas"
[Thu Oct 17 13:59:34 2019] [Err]:   File "C:\Users\quint\Anaconda3\lib\threading.py", line 917, in _bootstrap_inner
[Thu Oct 17 13:59:34 2019] [Err]:   File "C:\Users\quint\Anaconda3\lib\threading.py", line 917, in _bootstrap_inner
[Thu Oct 17 13:59:34 2019] [Err]:   File "C:\Users\quint\Anaconda3\lib\threading.py", line 917, in _bootstrap_inner
[Thu Oct 17 13:59:34 2019] [Err]:     response[:] = (func(*a, **kw), False)
[Thu Oct 17 13:59:34 2019] [Err]: Traceback (most recent call last):
[Thu Oct 17 13:59:34 2019] [Err]:   File "C:\Users\quint\Anaconda3\lib[Thu Oct 17 13:59:34 2019] [Err]:   File "C:\Us[Thu Oct 17 13:59:34 2019] [Err][Thu Oct 17 13:59:34 2019] [Err]:     self.run()
[Thu Oct 17 13:59:34 2019] [Err]:   File "C:\Users\quint\Anaconda3\lib\threading.py", line 917, in _bootstrap_inner
[Thu Oct 17 13:59:34 2019] [Err]:   File "C:\Users\quint\Anaconda3\lib\threading.py", line 917, in _bootstrap_inner
[Thu Oct 17 13:59:34 2019] [Err]: _tkinter.TclError: bad window path name ".!canvas"
[Thu Oct 17 13:59:34 2019] [Err]:     self.run()
[Thu Oct 17 13:59:34 2019] [Err]:   [Thu Oct 17 13:59:34 2019] [Err]: _tkinter.TclError: invalid command name ".!canvas"
[Thu Oct 17 13:59:34 2019] [Err]: Traceback (most recent call last):
[Thu Oct 17 13:59:34 2019] [Err]:   File "C:\Users\quint\Anaconda3\lib\threading.py", line 917, in _bootstrap_inner
[Thu Oct 17 13:59:34 2019] [Err]: _tkinter.TclError: invalid command name ".!canvas"
[Thu Oct 17 13:59:34 2019] [Err]: Traceback (most recent call last):
[Thu Oct 17 13:59:34 2019] [Err]:     self.run()
[Thu Oct 17 13:59:34 2019] [Err]:   File "C:\Users\quint\Anaconda3\lib\threading.py", line 865, in run
[Thu Oct 17 13:59:34 2019] [Err]:     self.run()
[Thu Oct 17 13:59:34 2019] [Err]:     response[:] = (func(*a, **kw), False)
[Thu Oct 17 13:59:34 2019] [Err]: Traceback (most recent call last):
[Thu Oct 17 13:59:34 2019] [Err]:     response[:] = (func(*a, **kw), False)
[Thu Oct 17 13:59:34 2019] [Err]: 
[Thu Oct 17 13:59:34 2019] [Err]:     response[:] = (func(*a, **kw), False)
[Thu Oct 17 13:59:34 2019] [Err]: _tkinter.TclError: invalid command name ".!canvas"
[Thu Oct 17 13:59:34 2019] [Err]: 
[Thu Oct 17 13:59:34 2019] [Err]: 
[Thu Oct 17 13:59:34 2019] [Err]:   File "C:\Users\quint\Anaconda3\lib\threading.py", line 917, in _bootstrap_inner
[Thu Oct 17 13:59:34 2019] [Err]: 
[Thu Oct 17 13:59:34 2019] [Err]: _tkinter.TclError: bad window path name ".!canvas"
[Thu Oct 17 13:59:34 2019] [Err]:     self.run()
[Thu Oct 17 13:59:34 2019] [Err]: _tkinter.TclError: invalid command name ".!canvas"
[Thu Oct 17 13:59:34 2019] [Err]:   File "C:\Users\quint\Anaconda3\lib\site-packages\threadsafe_tkinter\__init__.py", line 133, in process_requests
[Thu Oct 17 13:59:34 2019] [Err]:   File "C:\Users\quint\Anaconda3\lib\threading.py", line 917, in _bootstrap_inner
[Thu Oct 17 13:59:34 2019] [Err]: 
[Thu Oct 17 13:59:34 2019] [Err]:   File "C:\Users\quint\Anaconda3\lib\threading.py", line 917, in _bootstrap_inner
[Thu Oct 17 13:59:34 2019] [Err]:   File "C:\Users\quint\Anaconda3\lib\threading.py", line 865, in run
[Thu Oct 17 13:59:34 2019] [Err]:     self._target(*self._args, **self._kwargs)
as"
line 865, in run
[Thu Oct 17 13:59:34 2019] [Err]:     self._target(*self._args, **self._kwargs)
py", line 865, in run
[Thu Oct 17 13:59:34 2019] [Err]:   File "C:\Users\quint\Anaconda3\lib\threading.py", line 917, in _bootstrap_inner
[Thu Oct 17 13:59:34 2019] [Err]:   File "C:\Users\quint\Anaconda3\lib\threading.py", line 865, in run
[Thu Oct 17 13:59:34 2019] [Err]:     self.run()
[Thu Oct 17 13:59:34 2019] [Err]: 
[Thu Oct 17 13:59:34 2019] [Err]:     self._target(*self._args, **self._kwargs)
[Thu Oct 17 13:59:34 2019] [Err]: _tkinter.TclError: invalid command name ".!canvas"
[Thu Oct 17 13:59:34 2019] [Err]: 
[Thu Oct 17 13:59:34 2019] [Err]:   File "C:\Users\quint\Anaconda3\lib\threading.py", line 865, in run
[Thu Oct 17 13:59:34 2019] [Err]:     self._target(*self._args, **self._kwargs)
[Thu Oct 17 13:59:34 2019] [Err]:     self.run()
[Thu Oct 17 13:59:34 2019] [Err]:   File "C:\Users\quint\Anaconda3\lib\threading.py", line 917, in _bootstrap_inner
[Thu Oct 17 13:59:34 2019] [Err]:     self.run()
[Thu Oct 17 13:59:34 2019] [Err]:     self.run()
[Thu Oct 17 13:59:34 2019] [Err]:     self.run()
\quint\Anaconda3\lib\threading.py", line 865, in run
[Thu Oct 17 13:59:34 2019] [Err]:     self.run()
[Thu Oct 17 13:59:34 2019] [Err]:     self.run()
[Thu Oct 17 13:59:34 2019] [Err]:     self.run()
[Thu Oct 17 13:59:34 2019] [Err]:   File "C:\Users\quint\Documents\GitHub\QplayBubbles-Releaes\lib\title.py", line 55, in <lambda>
[Thu Oct 17 13:59:34 2019] [Err]:     self._target(*self._args, **self._kwargs)
[Thu Oct 17 13:59:34 2019] [Err]: _tkinter.TclError: invalid command name ".!canvas"
[Thu Oct 17 13:59:34 2019] [Err]:   File "C:\Users\quint\Anaconda3\lib\threading.py", line 865, in run
[Thu Oct 17 13:59:34 2019] [Err]: 
[Thu Oct 17 13:59:34 2019] [Err]:   File "C:\Users\quint\Anaconda3\lib\threading.py", line 917, in _bootstrap_inner
[Thu Oct 17 13:59:34 2019] [Err]:   File "C:\Users\quint\Anaconda3\lib\threading.py", line 917, in _bootstrap_inner
[Thu Oct 17 13:59:34 2019] [Err]:     self._target(*self._args, **self._kwargs)
[Thu Oct 17 13:59:34 2019] [Err]:     response[:] = (func(*a, **kw), False)
[Thu Oct 17 13:59:34 2019] [Err]: 
[Thu Oct 17 13:59:34 2019] [Err]: _tkinter.TclError: invalid command name ".!canvas"
[Thu Oct 17 13:59:34 2019] [Err]:   File "C:\Users\quint\Anaconda3\lib\threading.py", line 865, in run
[Thu Oct 17 13:59:34 2019] [Err]:     self.run()
[Thu Oct 17 13:59:34 2019] [Err]:   File "C:\Users\quint\Anaconda3\lib\threading.py", line 865, in run
[Thu Oct 17 13:59:34 2019] [Err]:   File "C:\Users\quint\Anaconda3\lib\threading.py", line 865, in run
[Thu Oct 17 13:59:34 2019] [Err]:     self.run()
[Thu Oct 17 13:59:34 2019] [Err]:   File "C:\Users\quint\Anaconda3\lib\threading.py", line 865, in run
[Thu Oct 17 13:59:34 2019] [Err]:   File "C:\Users\quint\Documents\GitHub\QplayBubbles-Releaes\lib\title.py", line 55, in <lambda>
[Thu Oct 17 13:59:34 2019] [Err]: 
[Thu Oct 17 13:59:34 2019] [Err]:     self._target(*self._args, **self._kwargs)
[Thu Oct 17 13:59:34 2019] [Err]:   File "C:\Users\quint\Anaconda3\lib\threading.py", line 865, in run
[Thu Oct 17 13:59:34 2019] [Err]:     self.run()
[Thu Oct 17 13:59:34 2019] [Err]:   File "C:\Users\quint\Documents\GitHub\QplayBubbles-Releaes\lib\title.py", line 55, in <lambda>
[Thu Oct 17 13:59:34 2019] [Err]:   File "C:\Users\quint\Anaconda3\lib\threading.py", line 865, in run
[Thu Oct 17 13:59:34 2019] [Err]:     self._target(*self._args, **self._kwargs)
[Thu Oct 17 13:59:34 2019] [Err]: 
[Thu Oct 17 13:59:34 2019] [Err]:     self._target(*self._args, **self._kwargs)
[Thu Oct 17 13:59:34 2019] [Err]:   File "C:\Users\quint\Documents\GitHub\QplayBubbles-Releaes\lib\title.py", line 55, in <lambda>
[Thu Oct 17 13:59:34 2019] [Err]:     self._target(*self._args, **self._kwargs)
[Thu Oct 17 13:59:34 2019] [Err]: 
[Thu Oct 17 13:59:34 2019] [Err]:     self.run()
[Thu Oct 17 13:59:34 2019] [Err]:   File "C:\Users\quint\Anaconda3\lib\threading.py", line 865, in run
[Thu Oct 17 13:59:34 2019] [Err]: _tkinter.TclError: invalid command name ".!canvas"
[Thu Oct 17 13:59:34 2019] [Err]:     self._target(*self._args, **self._kwargs)
[Thu Oct 17 13:59:34 2019] [Err]:   File "C:\Users\quint\Documents\GitHub\QplayBubbles-Releaes\lib\title.py", line 55, in <lambda>
[Thu Oct 17 13:59:34 2019] [Err]: 
[Thu Oct 17 13:59:34 2019] [Err]:   File "C:\Users\quint\Anaconda3\lib\threading.py", line 865, in run
[Thu Oct 17 13:59:34 2019] [Err]:     Thread(None, lambda: self.background.cleanup_bubs()).start()
itle.py", line 55, in <lambda>
[Thu Oct 17 13:59:34 2019] [Err]:   File "C:\Users\quint\Anaconda3\lib\threading.py", line 865, in run
[Thu Oct 17 13:59:34 2019] [Err]:   File "C:\Users\quint\Documents\GitHub\QplayBubbles-Releaes\lib\title.py", line 55, in <lambda>
[Thu Oct 17 13:59:34 2019] [Err]:     Thread(None, lambda: self.background.cleanup_bubs()).start()
[Thu Oct 17 13:59:34 2019] [Err]:   File "C:\Users\quint\Anaconda3\lib\threading.py", line 865, in run
[Thu Oct 17 13:59:34 2019] [Err]:     self._target(*self._args, **self._kwargs)
[Thu Oct 17 13:59:34 2019] [Err]:   File "C:\Users\quint\Documents\GitHub\QplayBubbles-Releaes\lib\title.py", line 55, in <lambda>
[Thu Oct 17 13:59:34 2019] [Err]:     self._target(*self._args, **self._kwargs)
[Thu Oct 17 13:59:34 2019] [Err]:   File "C:\Users\quint\Documents\GitHub\QplayBubbles-Releaes\lib\title.py", line 55, in <lambda>
[Thu Oct 17 13:59:34 2019] [Err]:     self._target(*self._args, **self._kwargs)
[Thu Oct 17 13:59:34 2019] [Err]: 
[Thu Oct 17 13:59:34 2019] [Err]:   File "C:\Users\quint\Documents\GitHub\QplayBubbles-Releaes\lib\title.py", line 55, in <lambda>
[Thu Oct 17 13:59:34 2019] [Err]:   File "C:\Users\quint\Anaconda3\lib\threading.py", line 865, in run
.py", line 55, in <lambda>
[Thu Oct 17 13:59:34 2019] [Err]:   File "C:\Users\quint\Documents\GitHub\QplayBubbles-Releaes\lib\title.py", line 114, in cleanup_bubs
[Thu Oct 17 13:59:34 2019] [Err]:     Thread(None, lambda: self.background.cleanup_bubs()).start()
[Thu Oct 17 13:59:34 2019] [Err]:   File "C:\Users\quint\Documents\GitHub\QplayBubbles-Releaes\lib\title.py", line 55, in <lambda>
[Thu Oct 17 13:59:34 2019] [Err]:     Thread(None, lambda: self.background.cleanup_bubs()).start()
[Thu Oct 17 13:59:34 2019] [Err]:     Thread(None, lambda: self.background.cleanup_bubs()).start()
[Thu Oct 17 13:59:34 2019] [Err]:     self._target(*self._args, **self._kwargs)
[Thu Oct 17 13:59:34 2019] [Err]:     self._target(*self._args, **self._kwargs)
[Thu Oct 17 13:59:34 2019] [Err]:     self._target(*self._args, **self._kwargs)
[Thu Oct 17 13:59:34 2019] [Err]:     Thread(None, lambda: self.background.cleanup_bubs()).start()
[Thu Oct 17 13:59:34 2019] [Err]:     self._target(*self._args, **self._kwargs)
[Thu Oct 17 13:59:34 2019] [Err]: 
[Thu Oct 17 13:59:34 2019] [Err]:     self._target(*self._args, **self._kwargs)
[Thu Oct 17 13:59:34 2019] [Err]:   File "C:\Users\quint\Documents\GitHub\QplayBubbles-Releaes\lib\title.py", line 55, in <lambda>
[Thu Oct 17 13:59:34 2019] [Err]:   File "C:\Users\quint\Documents\GitHub\QplayBu[Thu Oct 17 13:59:3[Thu Oct 17 13:59:34 2019] [Err]:     Thread(None, lambda: self.background.cleanup_bubs()).start()
[Thu Oct 17 13:59:34 2019] [Err]:   File "C:\Users\quint\Documents\GitHub\QplayBubbles-Releaes\lib\title.py", line 55, in <lambda>
[Thu Oct 17 13:59:34 2019] [Err]:     x, y, = get_coords(self._canvas, self.__bubbles[index])
[Thu Oct 17 13:59:34 2019] [Err]:   File "C:\Users\quint\Documents\GitHub\QplayBubbles-Releaes\lib\title.py", line 114, in cleanup_bubs
[Thu Oct 17 13:59:34 2019] [Err]:   File "C:\Users\quint\Documents\GitHub\QplayBubbles-Releaes\lib\title.py", line 55, in <lambda>
[Thu Oct 17 13:59:34 2019] [Err]:     Thread(None, lambda: self.background.cleanup_bubs()).start()
[Thu Oct 17 13:59:34 2019] [Err]:   File "C:\Users\quint\Documents\GitHub\QplayBubbles-Releaes\lib\title.py", line 114, in cleanup_bubs
[Thu Oct 17 13:59:34 2019] [Err]:   File "C:\Users\quint\Documents\GitHub\QplayBubbles-Releaes\lib\title.py", line 114, in cleanup_bubs
[Thu Oct 17 13:59:34 2019] [Err]:     self._target(*self._args, **self._kwargs)
[Thu Oct 17 13:59:34 2019] [Err]:   File "C:\Users\quint\Documents\GitHub\QplayBubbles-Releaes\lib\title.py", line 114, in cleanup_bubs
[Thu Oct 17 13:59:34 2019] [Err]:     Thread(None, lambda: self.background.cleanup_bubs()).start()
[Thu Oct 17 13:59:34 2019] [Err]:   File "C:\Users\quint\Documents\GitHub\QplayBubbles-Releaes\lib\title.py", line 55, in <lambda>
[Thu Oct 17 13:59:34 2019] [Err]:     Thread(None, lambda: self.background.cleanup_bubs()).start()
[Thu Oct 17 13:59:34 2019] [Err]:     Thread(None, lambda: self.background.cleanup_bubs()).start()
itle.py", line 114, in cleanup_bubs
[Thu Oct 17 13:59:34 2019] [Err]:   File "C:\Users\quint\Documents\GitHub\QplayBubbles-Releaes\lib\title.py", line 55, in <lambda>
[Thu Oct 17 13:59:34 2019] [Err]:     Thread(None, lambda: self.background.cleanup_bubs()).start()
[Thu Oct 17 13:59:34 2019] [Err]:   File "C:\Users\quint\Documents\GitHub\QplayBubbles-Releaes\lib\title.py", line 55, in <lambda>
[Thu Oct 17 13:59:34 2019] [Err]:   File "C:\Users\quint\Documents\GitHub\QplayBubbles-Releaes\lib\title.py", line 55, in <lambda>
[Thu Oct 17 13:59:34 2019] [Err]:   File "C:\Users\quint\Documents\GitHub\QplayBubbles-Releaes\lib\title.py", line 114, in cleanup_bubs
[Thu Oct 17 13:59:34 2019] [Err]:   File "C:\Users\quint\Documents\GitHub\QplayBubbles-Releaes\lib\title.py", line 114, in cleanup_bubs
[Thu Oct 17 13:59:34 2019] [Err]:   File "C:\Users\quint\Documents\GitHub\QplayBubbles-Releaes\lib\title.py", line 55, in <lambda>
[Thu Oct 17 13:59:34 2019] [Err]:     self._target(*self._args, **self._kwargs)
[Thu Oct 17 13:59:34 2019] [Err]:   File "C:\Users\quint\Documents\GitHub\QplayBubbles-Releaes\lib\title.py", line 55, in <lambda>
[Thu Oct 17 13:59:34 2019] [Err]:     x, y, = get_coords(self._canvas, self.__bubbles[index])
lib\utils\__init__.py", line 25, in get_coords
[Thu Oct 17 13:59:34 2019] [Err]:     Thread(None, lambda: self.background.cleanup_bubs()).start()
[Thu Oct 17 13:59:34 2019] [Err]:   File "C:\Users\quint\Documents\GitHub\QplayBubbles-Releaes\lib\title.py", line 114, in cleanup_bubs
[Thu Oct 17 13:59:34 2019] [Err]:     x, y, = get_coords(self._canvas, self.__bubbles[index])
[Thu Oct 17 13:59:34 2019] [Err]:   File "C:\Users\quint\Documents\GitHub\QplayBubbles-Releaes\lib\title.py", line 55, in <lambda>
[Thu Oct 17 13:59:34 2019] [Err]:   File "C:\Users\quint\Documents\GitHub\QplayBubbles-Releaes\lib\title.py", line 55, in <lambda>
[Thu Oct 17 13:59:34 2019] [Err]:     Thread(None, lambda: self.background.cleanup_bubs()).start()
[Thu Oct 17 13:59:34 2019] [Err]:     Thread(None, lambda: self.background.cleanup_bubs()).start()
[Thu Oct 17 13:59:34 2019] [Err]:   File "C:\Users\quint\Documents\GitHub\QplayBubbles-Releaes\lib\title.py", line 114, in cleanup_bubs
[Thu Oct 17 13:59:34 2019] [Err]:   File "C:\Users\quint\Documents\GitHub\QplayBubbles-Releaes\lib\title.py", line 114, in cleanup_bubs
[Thu Oct 17 13:59:34 2019] [Err]:     Thread(None, lambda: self.background.cleanup_bubs()).start()
[Thu Oct 17 13:59:34 2019] [Err]:     Thread(None, lambda: self.background.cleanup_bubs()).start()
[Thu Oct 17 13:59:34 2019] [Err]:   File "C:\Users\quint\Documents\GitHub\QplayBubbles-Releaes\lib\title.py", line 114, in cleanup_bubs
[Thu Oct 17 13:59:34 2019] [Err]:     Thread(None, lambda: self.background.cleanup_bubs()).start()
[Thu Oct 17 13:59:34 2019] [Err]:     x, y, = get_coords(self._canvas, self.__bubbles[index])
[Thu Oct 17 13:59:34 2019] [Err]:   File "C:\Users\quint\Documents\GitHub\QplayBubbles-Releaes\lib\title.py", line 114, in cleanup_bubs
[Thu Oct 17 13:59:34 2019] [Err]:     x, y, = get_coords(self._canvas, self.__bubbles[index])
[Thu Oct 17 13:59:34 2019] [Err]:   File "C:\Users\quint\Documents\GitHub\QplayBubbles-Releaes\lib\title.py", line 114, in cleanup_bubs
[Thu Oct 17 13:59:34 2019] [Err]:     Thread(None, lambda: self.background.cleanup_bubs()).start()
itle.py", line 55, in <lambda>
[Thu Oct 17 13:59:34 2019] [Err]:   File "C:\Users\quint\Documents\GitHub\QplayBubbles-Releaes\lib\title.py", line 114, in cleanup_bubs
[Thu Oct 17 13:59:34 2019] [Err]:     x, y, = get_coords(self._canvas, self.__bubbles[index])
[Thu Oct 17 13:59:34 2019] [Err]:   File "C:\Users\quint\Documents\GitHub\QplayBubbles-Releaes\lib\title.py", line 114, in cleanup_bubs
[Thu Oct 17 13:59:34 2019] [Err]:     Thread(None, lambda: self.background.cleanup_bubs()).start()
[Thu Oct 17 13:59:34 2019] [Err]:     x, y, = get_coords(self._canvas, self.__bubbles[index])
[Thu Oct 17 13:59:34 2019] [Err]:     x, y, = get_coords(self._canvas, self.__bubbles[index])
[Thu Oct 17 13:59:34 2019] [Err]:     Thread(None, lambda: self.background.cleanup_bubs()).start()
[Thu Oct 17 13:59:34 2019] [Err]:   File "C:\Users\quint\Documents\GitHub\QplayBubbles-Releaes\lib\title.py", line 55, in <lambda>
[Thu Oct 17 13:59:34 2019] [Err]:   File "C:\Users\quint\Documents\GitHub\QplayBubbles-Releaes\lib\utils\__init__.py", line 25, in get_coords
[Thu Oct 17 13:59:34 2019] [Err]:   File "C:\Users\quint\Documents\GitHub\QplayBubbles-Releaes\lib\title.py", line 114, in cleanup_bubs
[Thu Oct 17 13:59:34 2019] [Err]:   File "C:\Users\quint\Documents\GitHub\QplayBubbles-Releaes\lib\utils\__init__.py", line 25, in get_coords
[Thu Oct 17 13:59:34 2019] [Err]:   File "C:\Users\quint\Documents\GitHub\QplayBubbles-Releaes\lib\utils\__init__.py", line 25, in get_coords
[Thu Oct 17 13:59:34 2019] [Err]:     x, y, = get_coords(self._canvas, self.__bubbles[index])
[Thu Oct 17 13:59:34 2019] [Err]:   File "C:\Users\quint\Documents\GitHub\QplayBubbles-Releaes\lib\title.py", line 114, in cleanup_bubs
[Thu Oct 17 13:59:34 2019] [Err]:   File "C:\Users\quint\Documents\GitHub\QplayBubbles-Releaes\lib\utils\__init__.py", line 25, in get_coords
[Thu Oct 17 13:59:34 2019] [Err]:   File "C:\Users\quint\Documents\GitHub\QplayBubbles-Releaes\lib\title.py", line 114, in cleanup_bubs
[Thu Oct 17 13:59:34 2019] [Err]:     Thread(None, lambda: self.background.cleanup_bubs()).start()
[Thu Oct 17 13:59:34 2019] [Err]:     except TclError:
[Thu Oct 17 13:59:34 2019] [Err]:     x, y, = get_coords(self._canvas, self.__bubbles[index])
[Thu Oct 17 13:59:34 2019] [Err]:   File "C:\Users\quint\Documents\GitHub\QplayBubbles-Releaes\lib\title.py", line 114, in cleanup_bubs
[Thu Oct 17 13:59:34 2019] [Err]:   File "C:\Users\quint\Documents\GitHub\QplayBubbles-Releaes\lib\utils\__init__.py", line 25, in get_coords
[Thu Oct 17 13:59:34 2019] [Err]:   File "C:\Users\quint\Documents\GitHub\QplayBubbles-Releaes\lib\utils\__init__.py", line 25, in get_coords
[Thu Oct 17 13:59:34 2019] [Err]:   File "C:\Users\quint\Documents\GitHub\QplayBubbles-Releaes\lib\utils\__init__.py", line 25, in get_coords
[Thu Oct 17 13:59:34 2019] [Err]:     Thread(None, lambda: self.background.cleanup_bubs()).start()
[Thu Oct 17 13:59:34 2019] [Err]:     x, y, = get_coords(self._canvas, self.__bubbles[index])
[Thu Oct 17 13:59:34 2019] [Err]:   File "C:\Users\quint\Documents\GitHub\QplayBubbles-Releaes\lib\title.py", line 114, in cleanup_bubs
[Thu Oct 17 13:59:34 2019] [Err]:     x, y, = get_coords(self._canvas, self.__bubbles[index])
[Thu Oct 17 13:59:34 2019] [Err]:     x, y, = get_coords(self._canvas, self.__bubbles[index])
[Thu Oct 17 13:59:34 2019] [Err]:   File "C:\Users\quint\Documents\GitHub\QplayBubbles-Releaes\lib\utils\__init__.py", line 25, in get_co[Thu Oct 17 13:59:34 2019] [Err]:     x, y, = get_coords(self._canvas, self.__bubbles[index])
[Thu Oct 17 13:59:34 2019] [Err]:     x, y, = get_coords(self._canvas, self.__bubbles[index])
lib\utils\__init__.py", line 25, in get_coords
[Thu Oct 17 13:59:34 2019] [Err]: NameError: name 'TclError' is not defined
[Thu Oct 17 13:59:34 2019] [Err]:     x, y, = get_coords(self._canvas, self.__bubbles[index])
[Thu Oct 17 13:59:34 2019] [Err]:     except TclError:
[Thu Oct 17 13:59:34 2019] [Err]:     except TclError:
[Thu Oct 17 13:59:34 2019] [Err]:   File "C:\Users\quint\Documents\GitHub\QplayBubbles-Releaes\lib\utils\__init__.py", line 25, in get_coords
[Thu Oct 17 13:59:34 2019] [Err]:     except TclError:
[Thu Oct 17 13:59:34 2019] [Err]:   File "C:\Users\quint\Documents\GitHub\QplayBubbles-Releaes\lib\utils\__init__.py", line 25, in get_coords
[Thu Oct 17 13:59:34 2019] [Err]:     except TclError:
[Thu Oct 17 13:59:34 2019] [Err]:   File "C:\Users\quint\Documents\GitHub\QplayBubbles-Releaes\lib\title.py", line 114, in cleanup_bubs
[Thu Oct 17 13:59:34 2019] [Err]:   File "C:\Users\quint\Documents\GitHub\QplayBubbles-Releaes\lib\title.py", line 114, in cleanup_bubs
[Thu Oct 17 13:59:34 2019] [Err]:     x, y, = get_coords(self._canvas, self.__bubbles[index])
[Thu Oct 17 13:59:34 2019] [Err]:   File "C:\Users\quint\Documents\GitHub\QplayBubbles-Releaes\lib\utils\__init__.py", line 25, in get_coords
[Thu Oct 17 13:59:34 2019] [Err]:     x, y, = get_coords(self._canvas, self.__bubbles[index])
[Thu Oct 17 13:59:34 2019] [Err]:     except TclError:
[Thu Oct 17 13:59:34 2019] [Err]:     except TclError:
[Thu Oct 17 13:59:34 2019] [Err]:     x, y, = get_coords(self._canvas, self.__bubbles[index])
[Thu Oct 17 13:59:34 2019] [Err]:     x, y, = get_coords(self._canvas, self.__bubbles[index])
[Thu Oct 17 13:59:34 2019] [Err]:   File "C:\Users\quint\Documents\GitHub\QplayBubbles-Releaes\lib\utils\__init__.py", line 25, in get_coords
[Thu Oct 17 13:59:34 2019] [Err]:   File "C:\Users\quint\Documents\GitHub\QplayBubbles-Releaes\lib\title.py", line 114, in cleanup_bubs
[Thu Oct 17 13:59:34 2019] [Err]:     x, y, = get_coords(self._canvas, self.__bubbles[index])
[Thu Oct 17 13:59:34 2019] [Err]:     except TclError:
[Thu Oct 17 13:59:34 2019] [Err]:     x, y, = get_coords(self._canvas, self.__bubbles[index])
lib\title.py", line 114, in cleanup_bubs
ords
[Thu Oct 17 13:59:34 2019] [Err]:     except TclError:
[Thu Oct 17 13:59:34 2019] [Err]: NameError: name 'TclError' is not defined
[Thu Oct 17 13:59:34 2019] [Err]:   File "C:\Users\quint\Documents\GitHub\QplayBubbles-Releaes\lib\utils\__init__.py", line 25, in get_coords
[Thu Oct 17 13:59:34 2019] [Err]:     x, y, = get_coords(self._canvas, self.__bubbles[index])
[Thu Oct 17 13:59:34 2019] [Err]:     except TclError:
[Thu Oct 17 13:59:34 2019] [Err]:     except TclError:
[Thu Oct 17 13:59:34 2019] [Err]:   File "C:\Users\quint\Documents\GitHub\QplayBubbles-Releaes\lib\utils\__init__.py", line 25, in get_coords
[Thu Oct 17 13:59:34 2019] [Err]:   File "C:\Users\quint\Documents\GitHub\QplayBubbles-Releaes\lib\utils\__init__.py", line 25, in get_coords
[Thu Oct 17 13:59:34 2019] [Err]:   File "C:\Users\quint\Documents\GitHub\QplayBubbles-Releaes\lib\utils\__init__.py", line 25, in get_coords
[Thu Oct 17 13:59:34 2019] [Err]:   File "C:\Users\quint\Documents\GitHub\QplayBubbles-Releaes\lib\utils\__init__.py", line 25, in get_coords
[Thu Oct 17 13:59:34 2019] [Err]:   File "C:\Users\quint\Documents\GitHub\QplayBubbles-Releaes\lib\utils\__init__.py", line 25, in get_coords
[Thu Oct 17 13:59:34 2019] [Err]: NameError: name 'TclError' is not defined
[Thu Oct 17 13:59:34 2019] [Err]: NameError: name 'TclError' is not defined
[Thu Oct 17 13:59:34 2019] [Err]: NameError: name 'TclError' is not defined
[Thu Oct 17 13:59:34 2019] [Err]:     except TclError:
[Thu Oct 17 13:59:34 2019] [Err]: NameError: name 'TclError' is not defined
[Thu Oct 17 13:59:34 2019] [Err]:     x, y, = get_coords(self._canvas, self.__bubbles[index])
[Thu Oct 17 13:59:34 2019] [Err]:     except TclError:
[Thu Oct 17 13:59:34 2019] [Err]: NameError: name 'TclError' is not defined
[Thu Oct 17 13:59:34 2019] [Err]: NameError: name 'TclError' is not defined
[Thu Oct 17 13:59:34 2019] [Err]: 
[Thu Oct 17 13:59:34 2019] [Err]:     x, y, = get_coords(self._canvas, self.__bubbles[index])
[Thu Oct 17 13:59:34 2019] [Err]:   File "C:\Users\quint\Documents\GitHub\QplayBubbles-Releaes\lib\utils\__init__.py", line 25, in get_coords
[Thu Oct 17 13:59:34 2019] [Err]:     except TclError:
\Documents\GitHub\QplayBubbles-Releaes\lib\utils\__init__.py", line 25, in get_coords
[Thu Oct 17 13:59:34 2019] [Err]:   File "C:\Users\quint\Documents\GitHub\QplayBubbles-Releaes\lib\utils\__init__.py", line 25, in get_coords
[Thu Oct 17 13:59:34 2019] [Err]:     x, y, = get_coords(self._canvas, self.__bubbles[index])
[Thu Oct 17 13:59:34 2019] [Err]: NameError: name 'TclError' is not defined
[Thu Oct 17 13:59:34 2019] [Err]:     except TclError:
[Thu Oct 17 13:59:34 2019] [Err]:     except TclError:
[Thu Oct 17 13:59:34 2019] [Err]: 
[Thu Oct 17 13:59:34 2019] [Err]: NameError: name 'TclError' is not defined
[Thu Oct 17 13:59:34 2019] [Err]:   File "C:\Users\quint\Documents\GitHub\QplayBubbles-Releaes\lib\utils\__init__.py", line 25, in get_coords
[Thu Oct 17 13:59:34 2019] [Err]: NameError: name 'TclError' is not defined
[Thu Oct 17 13:59:34 2019] [Err]: 
[Thu Oct 17 13:59:34 2019] [Err]:     except TclError:
[Thu Oct 17 13:59:34 2019] [Err]: NameError: name 'TclError' is not defined
[Thu Oct 17 13:59:34 2019] [Err]:   File "C:\Users\quint\Documents\GitHub\QplayBubbles-Releaes\lib\utils\__init__.py", line 25, in get_coords
[Thu Oct 17 13:59:34 2019] [Err]: 
[Thu Oct 17 13:59:34 2019] [Err]:     except TclError:
[Thu Oct 17 13:59:34 2019] [Err]: 
[Thu Oct 17 13:59:34 2019] [Err]:   File "C:\Users\quint\Documents\GitHub\QplayBubbles-Releaes\lib\utils\__init__.py", line 25, in get_coords
[Thu Oct 17 13:59:34 2019] [Err]:     except TclError:
[Thu Oct 17 13:59:34 2019] [Err]: 
[Thu Oct 17 13:59:34 2019] [Err]: NameError: name 'TclError' is not defined
[Thu Oct 17 13:59:34 2019] [Err]: 
[Thu Oct 17 13:59:34 2019] [Err]:     except TclError:
[Thu Oct 17 13:59:34 2019] [Err]: 
[Thu Oct 17 13:59:34 2019] [Err]: NameError: name 'TclError' is not defined
[Thu Oct 17 13:59:34 2019] [Err]:     except TclError:
[Thu Oct 17 13:59:34 2019] [Err]: NameError: name 'TclError' is not defined
ayBubbles-Releaes\lib\utils\__init__.py", line 25, in get_coords
[Thu Oct 17 13:59:34 2019] [Err]: 
[Thu Oct 17 13:59:34 2019] [Err]:     except TclError:
[Thu Oct 17 13:59:34 2019] [Err]: 
[Thu Oct 17 13:59:34 2019] [Err]:     except TclError:
[Thu Oct 17 13:59:34 2019] [Err]: 
[Thu Oct 17 13:59:34 2019] [Err]: NameError: name 'TclError' is not defined
[Thu Oct 17 13:59:34 2019] [Err]: NameError: name 'TclError' is not defined
[Thu Oct 17 13:59:34 2019] [Err]: NameError: name 'TclError' is not defined
[Thu Oct 17 13:59:34 2019] [Err]: 
[Thu Oct 17 13:59:34 2019] [Err]: NameError: name 'TclError' is not defined
[Thu Oct 17 13:59:34 2019] [Err]: NameError: name 'TclError' is not defined
[Thu Oct 17 13:59:34 2019] [Err]: 
[Thu Oct 17 13:59:34 2019] [Err]: 
[Thu Oct 17 13:59:34 2019] [Err]: NameError: name 'TclError' is not defined
[Thu Oct 17 13:59:34 2019] [Err]: NameError: name 'TclError' is not defined
[Thu Oct 17 13:59:34 2019] [Err]:     except TclError:
[Thu Oct 17 13:59:34 2019] [Err]:     except TclError:
[Thu Oct 17 13:59:34 2019] [Err]:     except TclError:
[Thu Oct 17 13:59:34 2019] [Err]: 
[Thu Oct 17 13:59:34 2019] [Err]:     except TclError:
ror' is not defined
[Thu Oct 17 13:59:34 2019] [Err]: NameError: name 'TclError' is not defined
[Thu Oct 17 13:59:34 2019] [Err]: 
[Thu Oct 17 13:59:34 2019] [Err]: NameError: name 'TclError' is not defined
[Thu Oct 17 13:59:34 2019] [Err]: NameError: name 'TclError' is not defined
[Thu Oct 17 13:59:34 2019] [Err]: NameError: name 'TclError' is not defined
[Thu Oct 17 13:59:34 2019] [Err]: NameError: name 'TclError' is not defined
[Thu Oct 17 13:59:34 2019] [Err]: 
[Thu Oct 17 13:59:34 2019] [Err]: 
[Thu Oct 17 13:59:34 2019] [Err]: 
[Thu Oct 17 13:59:34 2019] [Err]: 
[Thu Oct 17 13:59:34 2019] [Err]: 
[Thu Oct 17 13:59:34 2019] [Err]: 
[Thu Oct 17 13:59:34 2019] [Err]: NameError: name 'TclError' is not defined
[Thu Oct 17 13:59:34 2019] [Err]: 
[Thu Oct 17 13:59:34 2019] [Err]: 
[Thu Oct 17 13:59:34 2019] [Err]: 
[Thu Oct 17 13:59:34 2019] [Err]: 
[Thu Oct 17 13:59:34 2019] [Err]: 
[Thu Oct 17 13:59:34 2019] [Err]: 
[Thu Oct 17 13:59:34 2019] [Err]: 
[Thu Oct 17 13:59:34 2019] [Err]: 
